Workbook

Sheet Foglio1
A2: SQUADRE | C2: gol e assist lasciati in panchina | G2: record
A3: punti | C3: cannoniere
A4: punti mod dif | C4: assistman | G4: pt in una giornata | H4: max e min
A5: GOL FATTI-SUBITI REALI | C5: portiere con piu clean shit | G5: pt subiti in una giornata | H5: max e min
C6: miglior e peggior punteggio tot
C7: miglior attacco e difesa
C8: MEDIA GOL A PARTITA F E S
C9: PUNTI SUBITI SQ AVVERSARIE
C10: GOAL SUBIT SQ AVVERSARIE
C11: MEDIA ROSA
A13: GIOCATORI | C13: TIT
C14: GOL FATTI TIT
A15: cannonieri | C15: ASSIST FATTI TIT
A16: assist | C16: GOL SUBITI TIT
A17: clean sheets | C17: ASSIST SUBITI TIT
C19: PANCHINA
C20: GOL FATTI
A21: TOP TEN | C21: ASSIST FATTI
A22: tito 11 | C22: GOL SUBITI
A23: port | C23: ASSIST SUBITI
A24: ddif
A25: centr | C25: PORTIERE
A26: att
C27: GOL SUBITI TIT
C28: CLEAN SHEET TIT
C29: GOL SUBITI PANCA
C30: CLEAN SHEET PANCA
C32: SANZIONI
C34: AMMONIZ TIT
C35: AMMONIZ PANCA
C36: ESPULSIONI TIT
C37: ESPULSIONI PANCA
C39: GIOCARE IN MENO
C41: IO
C42: AVVERSARI

Sheet CLASS BEST TEAMS
X1: TITOLARI | AB1: GENERALE
C3: 1 | D3: =_xlfn.XLOOKUP(E3,SQUADRE!$BI$4:$BP$4,SQUADRE!$BI$3:$BP$3) -> #VALUE! | E3: {=IF($X$3="PT LAST GG",INDEX(_xlfn._xlws.SORT(SQUADRE!$Z$4:$BH$11,_xlfn.XLOOKUP(X3,$AK$3:$BR$3,$AK$4:$BR$4),1),_xlfn.SEQUENCE(8),1),INDEX(_xlfn._xlws.SORT(SQUADRE!$Z$4:$BH$11,_xlfn.XLOOKUP(X3,$AK$3:$BR$3,$AK$4:$BR$4),-1),_xlfn.SEQUENCE(8),1))} -> PESCICULINI FC | F3: -31 | G3: {=IF(X3="crescita rosa",IF(X3="PT LAST GG",INDEX(_xlfn._xlws.SORT(SQUADRE!$Z$4:$BH$11,_xlfn.XLOOKUP($X$3,$AK$3:$BR$3,$AK$4:$BR$4),1),_xlfn.SEQUENCE(8),_xlfn.XLOOKUP(X3,$AK$3:$BR$3,$AK$4:$BR$4)),INDEX(_xlfn._xlws.SORT(SQUADRE!$Z$4:$BH$11,_xlfn.XLOOKUP(X3,$AK$3:$BR$3,$AK$4:$BR$4),-1),_xlfn.SEQUENCE(8),_xlfn.XLOOKUP(X3,$AK$3:$BR$3,$AK$4:$BR$4)))+F3,IF(X3="PT LAST GG",INDEX(_xlfn._xlws.SORT(SQUADRE!$Z$4:$BH$11,_xlfn.XLOOKUP($X$3,$AK$3:$BR$3,$AK$4:$BR$4),1),_xlfn.SEQUENCE(8),_xlfn.XLOOKUP(X3,$AK$3:$BR$3,$AK$4:$BR$4)),INDEX(_xlfn._xlws.SORT(SQUADRE!$Z$4:$BH$11,_xlfn.XLOOKUP(X3,$AK$3:$BR$3,$AK$4:$BR$4),-1),_xlfn.SEQUENCE(8),_xlfn.XLOOKUP(X3,$AK$3:$BR$3,$AK$4:$BR$4))))} -> 1 | H3: =IF(RIGHT(TEXT(G3, "0," & REPT("0", _xlfn.XLOOKUP($X$3,SQUADRE!$AA$3:$BH$3,SQUADRE!$AA$2:$BH$2))),1)=",",LEFT(G3,LEN(G3)),TEXT(G3, "0," & REPT("0", _xlfn.XLOOKUP($X$3,SQUADRE!$AA$3:$BH$3,SQUADRE!$AA$2:$BH$2)))) -> 1 | K3: AMM | X3: crescita rosa | AK3: PT | AL3: BONUS | AM3: FANTA PT | AN3: MOD DIF | AO3: PT TOT | AP3: PT BEST | AQ3: BONUS BEST | AR3: FANTAPT BEST | AS3: MOD DIFESA BEST | AT3: MEDIA VOTO TIT | AU3: MEDIA FVOTO TIT | AV3: FVOTO TOT | AW3: MEDIA VOTO BEST | AX3: MEDIA FVOTO BEST | AY3: delta pt | AZ3: delta bonus | BA3: delta fanta pt | BC3: PT BEST GG | BD3: PT LAST GG | BE3: GOL fatti | BF3: GOL SUBITI | BG3: ASSIST FATTI | BH3: AMM | BI3: ESP | BJ3: RIG OK | BK3: RIG KO | BL3: GOL DIFESA | BM3: GOL CC | BN3: GOL ATT | BO3: CLN SHEET | BP3: f1 | BQ3: royal battle | BR3: crescita rosa
C4: 2 | D4: =_xlfn.XLOOKUP(E4,SQUADRE!$BI$4:$BP$4,SQUADRE!$BI$3:$BP$3) -> #VALUE! | E4: SAN GRIA | F4: -9 | G4: -10 | H4: =IF(RIGHT(TEXT(G4, "0," & REPT("0", _xlfn.XLOOKUP($X$3,SQUADRE!$AA$3:$BH$3,SQUADRE!$AA$2:$BH$2))),1)=",",LEFT(G4,LEN(G4)),TEXT(G4, "0," & REPT("0", _xlfn.XLOOKUP($X$3,SQUADRE!$AA$3:$BH$3,SQUADRE!$AA$2:$BH$2)))) -> -10 | AK4: 2 | AL4: 3 | AM4: 4 | AN4: 5 | AO4: 6 | AP4: 7 | AQ4: 8 | AR4: 9 | AS4: 10 | AT4: 11 | AU4: 12 | AV4: 13 | AW4: 14 | AX4: 15 | AY4: 16 | AZ4: 17 | BA4: 18 | BB4: 19 | BC4: 20 | BD4: 21 | BE4: 22 | BF4: 23 | BG4: 24 | BH4: 25 | BI4: 26 | BJ4: 27 | BK4: 28 | BL4: 29 | BM4: 30 | BN4: 31 | BO4: 32 | BP4: 33 | BQ4: 34 | BR4: 35 | BS4: 36 | BT4: 37 | BU4: 38 | BV4: 39 | BW4: 40 | BX4: 41 | BY4: 42 | BZ4: 43
C5: 3 | D5: =_xlfn.XLOOKUP(E5,SQUADRE!$BI$4:$BP$4,SQUADRE!$BI$3:$BP$3) -> #VALUE! | E5: AC ASPARAGHESE | F5: -17 | G5: -31 | H5: =IF(RIGHT(TEXT(G5, "0," & REPT("0", _xlfn.XLOOKUP($X$3,SQUADRE!$AA$3:$BH$3,SQUADRE!$AA$2:$BH$2))),1)=",",LEFT(G5,LEN(G5)),TEXT(G5, "0," & REPT("0", _xlfn.XLOOKUP($X$3,SQUADRE!$AA$3:$BH$3,SQUADRE!$AA$2:$BH$2)))) -> -31 | AK5: Somma dei punti in classifica tenendo conto solamente dei voti sul campo | AL5: Somma dei punti ottenuti solamente con i bonus e i malus | AM5: Somma dei fantapunti esclusi punti per chi gioca in casa e del modificatore difesa | AN5: Punti ottenuti solamente col modificatore difesa | AO5: Somma dei punti ottenuti totali esclusi i punt per chi gioca in casa | AP5: Somma dei punti dei soli voti degli 11 migliori giocatori seguendo i moduli disponibili | AQ5: Somma dei punti dei bonus con gli 11 migliri giocatori | AR5: Somma dei fanta punti totali degli 11 migliori giocatori | AT5: Media voto degli 11 titolari (solo voti sul campo) | AU5: FANTAMEDIAVOTO DEGLI 11 TITOLARI | AV5: TOT PUNTEGGIO | AW5: MEDIA VOTO MIGLIOR FORMAZIONE POSSIBILE | AX5: MEDIA FANTA VOTO MIGLIOR FORMAZIONE POSSIBILE | AY5: DIFFERENZA TRA I PUNTI DELLA FORMAZIONE TITOLARE E QUELLA MIGLORE POSSIBILE | AZ5: DIFFERENZA TRA I PUNTI BONUS DELLA FORMAZIONE TITOLARE E QUELLA MIGLORE POSSIBILE | BA5: DIFFERENZA TRA I FANTAPUNTI DELLA FORMAZIONE TITOLARE E QUELLA MIGLORE POSSIBILE | BC5: MIGLIOR PUNTEGGIO DI GIORNATA | BD5: PEGGIOR PUNTEGGIO DI GIORNATA | BE5: gol effettivamente segnati dai giocatori titolari | BF5: gol effettivamente segnati dai giocatori titolari della squadra avversaria | BG5: assist titolari | BH5: ammonizioni titolari | BI5: espulsioni titolari | BJ5: rigori segnati titolari | BK5: rigori sbagliati titolari | BL5: gol segnati dai difensori titolari | BM5: gol segnati dai centrocampisti titolari | BN5: gol segnati dagli attaccanti titolari | BO5: clean sheets dei portieri titolari | BP5: ogni giornata da 8 a 1 pt a seconda dei punti fatti | BQ5: tre punti per ogni vittoria contro tutte le altre sette ,1 per ogni pareggio e 0 per ogni sconfitta(contano i gol fatti in base ai punti) | BR5: differenza qi/qa
C6: 4 | D6: =_xlfn.XLOOKUP(E6,SQUADRE!$BI$4:$BP$4,SQUADRE!$BI$3:$BP$3) -> #VALUE! | E6: APPAREGGIATO | F6: -18 | G6: -35 | H6: =IF(RIGHT(TEXT(G6, "0," & REPT("0", _xlfn.XLOOKUP($X$3,SQUADRE!$AA$3:$BH$3,SQUADRE!$AA$2:$BH$2))),1)=",",LEFT(G6,LEN(G6)),TEXT(G6, "0," & REPT("0", _xlfn.XLOOKUP($X$3,SQUADRE!$AA$3:$BH$3,SQUADRE!$AA$2:$BH$2)))) -> -35
C7: 5 | D7: =_xlfn.XLOOKUP(E7,SQUADRE!$BI$4:$BP$4,SQUADRE!$BI$3:$BP$3) -> #VALUE! | E7: ATL IMPROVVISATO | F7: -25 | G7: -49 | H7: =IF(RIGHT(TEXT(G7, "0," & REPT("0", _xlfn.XLOOKUP($X$3,SQUADRE!$AA$3:$BH$3,SQUADRE!$AA$2:$BH$2))),1)=",",LEFT(G7,LEN(G7)),TEXT(G7, "0," & REPT("0", _xlfn.XLOOKUP($X$3,SQUADRE!$AA$3:$BH$3,SQUADRE!$AA$2:$BH$2)))) -> -49
C8: 6 | D8: =_xlfn.XLOOKUP(E8,SQUADRE!$BI$4:$BP$4,SQUADRE!$BI$3:$BP$3) -> #VALUE! | E8: PARTIZAN DEGRADO | F8: -10 | G8: -51 | H8: =IF(RIGHT(TEXT(G8, "0," & REPT("0", _xlfn.XLOOKUP($X$3,SQUADRE!$AA$3:$BH$3,SQUADRE!$AA$2:$BH$2))),1)=",",LEFT(G8,LEN(G8)),TEXT(G8, "0," & REPT("0", _xlfn.XLOOKUP($X$3,SQUADRE!$AA$3:$BH$3,SQUADRE!$AA$2:$BH$2)))) -> -51
C9: 7 | D9: =_xlfn.XLOOKUP(E9,SQUADRE!$BI$4:$BP$4,SQUADRE!$BI$3:$BP$3) -> #VALUE! | E9: SESTO ASENSIO | F9: -40 | G9: -60 | H9: =IF(RIGHT(TEXT(G9, "0," & REPT("0", _xlfn.XLOOKUP($X$3,SQUADRE!$AA$3:$BH$3,SQUADRE!$AA$2:$BH$2))),1)=",",LEFT(G9,LEN(G9)),TEXT(G9, "0," & REPT("0", _xlfn.XLOOKUP($X$3,SQUADRE!$AA$3:$BH$3,SQUADRE!$AA$2:$BH$2)))) -> -60
C10: 8 | D10: =_xlfn.XLOOKUP(E10,SQUADRE!$BI$4:$BP$4,SQUADRE!$BI$3:$BP$3) -> #VALUE! | E10: HERTHA VERNELLO | F10: -64 | G10: -128 | H10: =IF(RIGHT(TEXT(G10, "0," & REPT("0", _xlfn.XLOOKUP($X$3,SQUADRE!$AA$3:$BH$3,SQUADRE!$AA$2:$BH$2))),1)=",",LEFT(G10,LEN(G10)),TEXT(G10, "0," & REPT("0", _xlfn.XLOOKUP($X$3,SQUADRE!$AA$3:$BH$3,SQUADRE!$AA$2:$BH$2)))) -> -128 | K10: =_xlfn.XLOOKUP(X3,AK3:BR3,AK5:BR5) -> differenza qi/qa

Sheet CLASS BEST PLAYERS
A1: gg
A2: 35 | B2: GOL
A5: 1 | B5: =_xlfn.IFNA(_xlfn.XLOOKUP(_xlfn.XLOOKUP(C5,GIOCATORI!$B:$B,GIOCATORI!$C:$C),SQUADRE!$BI$4:$BP$4,SQUADRE!$BI$3:$BP$3),"") -> #VALUE! | C5: {=INDEX(_xlfn._xlws.SORT(Tabella1[], MATCH(B2,Tabella1[#Headers], 0), -1), _xlfn.SEQUENCE(5),2)} -> Martinez L. | D5: {=INDEX(_xlfn._xlws.SORT(Tabella1[], MATCH(B2, Tabella1[#Headers], 0), -1), _xlfn.SEQUENCE(5),_xlfn.XLOOKUP(B2,Tabella1[[#Headers],[GOL]:[TOT FVOTO TIT]],GIOCATORI!$D$662:$T$662))} -> 16 | E5: =IF(ISNUMBER(SEARCH("voto", $B$2)),TEXT(D5, "0," & REPT("0", 2)),TEXT(D5, "0" & REPT("0", 0))) -> 16 | G5: 6 | H5: =_xlfn.IFNA(_xlfn.XLOOKUP(_xlfn.XLOOKUP(I5,GIOCATORI!$B:$B,GIOCATORI!$C:$C),SQUADRE!$BI$4:$BP$4,SQUADRE!$BI$3:$BP$3),"") -> #VALUE! | I5: {=INDEX(_xlfn._xlws.SORT(Tabella1[], MATCH(B2, Tabella1[#Headers], 0), -1), _xlfn.SEQUENCE(5, ,6),2)} -> Simeone | J5: {=INDEX(_xlfn._xlws.SORT(Tabella1[], MATCH(B2, Tabella1[#Headers], 0), -1), _xlfn.SEQUENCE(5, ,6),_xlfn.XLOOKUP(B2,Tabella1[[#Headers],[GOL]:[TOT FVOTO TIT]],GIOCATORI!$D$662:$T$662))} -> 11 | K5: =IF(ISNUMBER(SEARCH("voto", $B$2)),TEXT(J5, "0," & REPT("0", 2)),TEXT(J5, "0" & REPT("0", 0))) -> 11
A6: 2 | B6: =_xlfn.IFNA(_xlfn.XLOOKUP(_xlfn.XLOOKUP(C6,GIOCATORI!$B:$B,GIOCATORI!$C:$C),SQUADRE!$BI$4:$BP$4,SQUADRE!$BI$3:$BP$3),"") -> #VALUE! | C6: Malen | D6: 14 | E6: =IF(ISNUMBER(SEARCH("voto", $B$2)),TEXT(D6, "0," & REPT("0", 2)),TEXT(D6, "0" & REPT("0", 0))) -> 14 | G6: 7 | H6: =_xlfn.IFNA(_xlfn.XLOOKUP(_xlfn.XLOOKUP(I6,GIOCATORI!$B:$B,GIOCATORI!$C:$C),SQUADRE!$BI$4:$BP$4,SQUADRE!$BI$3:$BP$3),"") -> #VALUE! | I6: Thuram | J6: 11 | K6: =IF(ISNUMBER(SEARCH("voto", $B$2)),TEXT(J6, "0," & REPT("0", 2)),TEXT(J6, "0" & REPT("0", 0))) -> 11
A7: 3 | B7: =_xlfn.IFNA(_xlfn.XLOOKUP(_xlfn.XLOOKUP(C7,GIOCATORI!$B:$B,GIOCATORI!$C:$C),SQUADRE!$BI$4:$BP$4,SQUADRE!$BI$3:$BP$3),"") -> #VALUE! | C7: Douvikas | D7: 13 | E7: =IF(ISNUMBER(SEARCH("voto", $B$2)),TEXT(D7, "0," & REPT("0", 2)),TEXT(D7, "0" & REPT("0", 0))) -> 13 | G7: 8 | H7: =_xlfn.IFNA(_xlfn.XLOOKUP(_xlfn.XLOOKUP(I7,GIOCATORI!$B:$B,GIOCATORI!$C:$C),SQUADRE!$BI$4:$BP$4,SQUADRE!$BI$3:$BP$3),"") -> #VALUE! | I7: Krstovic | J7: 10 | K7: =IF(ISNUMBER(SEARCH("voto", $B$2)),TEXT(J7, "0," & REPT("0", 2)),TEXT(J7, "0" & REPT("0", 0))) -> 10
A8: 4 | B8: =_xlfn.IFNA(_xlfn.XLOOKUP(_xlfn.XLOOKUP(C8,GIOCATORI!$B:$B,GIOCATORI!$C:$C),SQUADRE!$BI$4:$BP$4,SQUADRE!$BI$3:$BP$3),"") -> #VALUE! | C8: Hojlund | D8: 12 | E8: =IF(ISNUMBER(SEARCH("voto", $B$2)),TEXT(D8, "0," & REPT("0", 2)),TEXT(D8, "0" & REPT("0", 0))) -> 12 | G8: 9 | H8: =_xlfn.IFNA(_xlfn.XLOOKUP(_xlfn.XLOOKUP(I8,GIOCATORI!$B:$B,GIOCATORI!$C:$C),SQUADRE!$BI$4:$BP$4,SQUADRE!$BI$3:$BP$3),"") -> #VALUE! | I8: Yildiz | J8: 10 | K8: =IF(ISNUMBER(SEARCH("voto", $B$2)),TEXT(J8, "0," & REPT("0", 2)),TEXT(J8, "0" & REPT("0", 0))) -> 10
A9: 5 | B9: =_xlfn.IFNA(_xlfn.XLOOKUP(_xlfn.XLOOKUP(C9,GIOCATORI!$B:$B,GIOCATORI!$C:$C),SQUADRE!$BI$4:$BP$4,SQUADRE!$BI$3:$BP$3),"") -> #VALUE! | C9: Paz N. | D9: 11 | E9: =IF(ISNUMBER(SEARCH("voto", $B$2)),TEXT(D9, "0," & REPT("0", 2)),TEXT(D9, "0" & REPT("0", 0))) -> 11 | G9: 10 | H9: =_xlfn.IFNA(_xlfn.XLOOKUP(_xlfn.XLOOKUP(I9,GIOCATORI!$B:$B,GIOCATORI!$C:$C),SQUADRE!$BI$4:$BP$4,SQUADRE!$BI$3:$BP$3),"") -> #VALUE! | I9: Scamacca | J9: 9 | K9: =IF(ISNUMBER(SEARCH("voto", $B$2)),TEXT(J9, "0," & REPT("0", 2)),TEXT(J9, "0" & REPT("0", 0))) -> 9
A13: 11
A14: 12
A15: 13
A16: 14
A17: 15
A18: 16
A19: 17
A20: 18
A21: 19
A22: 20
A23: 21
A24: 22
... A61: 59
D500: 1 | E500: 2 | F500: 3 | G500: 4 | H500: 5 | I500: 6 | J500: 7 | K500: 8 | L500: 9 | M500: 10 | N500: 11 | O500: 12

Sheet dsh sq
B2: =_xlfn.IFNA(_xlfn.XLOOKUP(F3,SQUADRE!BI4:BP4,SQUADRE!BI3:BP3),"svincolato") -> svincolato
F3: =_xlfn.XLOOKUP(M3,GIOCATORI!$B$3:$B$524,GIOCATORI!$C$3:$C$524) | M3: Kelly L.
M6: GENERALE | U6: titolare in fantalega
F7: Media VOTO | H7: Media FVOTO | J7: Totale FVOTO
F8: =_xlfn.XLOOKUP($M$3,GIOCATORI!$B$3:$B$534,GIOCATORI!$M$3:$M$534) -> 6.0151515 | H8: =_xlfn.XLOOKUP($M$3,GIOCATORI!$B$3:$B$534,GIOCATORI!$N$3:$N$534) -> 6.0757576 | J8: =_xlfn.XLOOKUP($M$3,GIOCATORI!$B$3:$B$534,GIOCATORI!$O$3:$O$534) -> 200.5 | M8: PARTITE | O8: =_xlfn.XLOOKUP($M$3,GIOCATORI!$B:$B,GIOCATORI!Q:Q) -> #REF! | Q8: GOL | S8: =SUMIFS([1]!Tabella1[[Gol ]],[1]!Tabella1[Nome],$M$3,[1]!Tabella1[N° FantaTit],1) -> 0 | U8: PARTITE | W8: =_xlfn.XLOOKUP($M$3,GIOCATORI!$B:$B,GIOCATORI!R:R) -> #REF! | Y8: GOL | AA8: =SUMIFS([1]!Tabella1[[Gol ]],[1]!Tabella1[Nome],$M$3,[1]!Tabella1[N° FantaTit],1) -> 0
F9: =_xlfn.RANK.EQ(_xlfn.XLOOKUP($M$3,GIOCATORI!$B:$B,GIOCATORI!M:M),GIOCATORI!M:M,0) -> 182 | H9: =_xlfn.RANK.EQ(_xlfn.XLOOKUP($M$3,GIOCATORI!$B:$B,GIOCATORI!N:N),GIOCATORI!N:N,0) -> 229 | J9: =_xlfn.RANK.EQ(_xlfn.XLOOKUP($M$3,GIOCATORI!B:B,GIOCATORI!O:O),GIOCATORI!O:O,0) -> 67 | M9: MEDIA VOTO | O9: =_xlfn.XLOOKUP($M$3,GIOCATORI!$B:$B,GIOCATORI!M:M) -> 6.0151515 | Q9: ASSIST | S9: =SUMIFS([1]!Tabella1[Ass],[1]!Tabella1[Nome],M3,[1]!Tabella1[N° FantaTit],1) -> 0 | U9: MEDIA VOTO | W9: =AVERAGEIFS([1]!Tabella1[Voto],[1]!Tabella1[Nome],$M$3,[1]!Tabella1[N° FantaTit],1) -> #DIV/0! | Y9: ASSIST | AA9: =SUMIFS([1]!Tabella1[Ass],[1]!Tabella1[Nome],$M$3,[1]!Tabella1[N° FantaTit],1) -> 0
F10: =F9&"°" -> 182° | H10: =H9&"°" -> 229° | J10: =J9&"°" -> 67° | M10: MEDIA FVOTO | O10: =_xlfn.XLOOKUP($M$3,GIOCATORI!$B:$B,GIOCATORI!N:N) -> 6.0757576 | Q10: RIGORI OK | S10: =SUMIFS([1]!Tabella1[Rf],[1]!Tabella1[Nome],$M$3,[1]!Tabella1[N° FantaTit],1) -> 0 | U10: MEDIA FVOTO | W10: =_xlfn.XLOOKUP($M$3,GIOCATORI!$B:$B,GIOCATORI!S:S) | Y10: RIGORI OK | AA10: =SUMIFS([1]!Tabella1[Rf],[1]!Tabella1[Nome],$M$3,[1]!Tabella1[N° FantaTit],1) -> 0
M11: TOT FVOTO | O11: =_xlfn.XLOOKUP($M$3,GIOCATORI!$B:$B,GIOCATORI!O:O) -> 200.5 | Q11: RIGORI KO | S11: =SUMIFS([1]!Tabella1[Rs],[1]!Tabella1[Nome],$M$3,[1]!Tabella1[N° FantaTit],1) -> 0 | U11: TOT FVOTO | W11: =_xlfn.XLOOKUP($M$3,GIOCATORI!$B:$B,GIOCATORI!T:T) | Y11: RIGORI KO | AA11: =SUMIFS([1]!Tabella1[Rs],[1]!Tabella1[Nome],$M$3,[1]!Tabella1[N° FantaTit],1) -> 0
B13: GIOCATE | D13: AMM | F13: ESP | H13: GOL | J13: ASS
B14: =_xlfn.XLOOKUP($M$3,GIOCATORI!$B$3:$B$534,GIOCATORI!$Q$3:$Q$534) -> #REF! | D14: =_xlfn.XLOOKUP($M$3,GIOCATORI!$B$3:$B$534,GIOCATORI!$J$3:$J$534) -> 4 | F14: =_xlfn.XLOOKUP($M$3,GIOCATORI!$B$3:$B$534,GIOCATORI!$K$3:$K$534) -> 0 | H14: =_xlfn.XLOOKUP($M$3,GIOCATORI!$B$3:$B$534,GIOCATORI!$D$3:$D$534) -> 1 | J14: =_xlfn.XLOOKUP($M$3,GIOCATORI!$B$3:$B$534,GIOCATORI!$E$3:$E$534) -> 1

Sheet CATEGORIE
A1: 1 | B1: VOTO
A2: 2 | B2: BONUS
A3: 3 | B3: FVOTO
A4: 4 | B4: MOD DIF
A5: 5 | B5: PT TOT
A6: 6 | B6: PT CLASS
A7: 7 | B7: BONUS BEST
A8: 8 | B8: PT BEST
A9: 9 | B9: MEDIA VOTO TIT
A10: 10 | B10: MEDIA FVOTO TIT
A11: 11
A12: 12 | B12: MEDIA VOTO BEST
A13: 13 | B13: MEDIA FVOTO BEST
A14: 14 | B14: delta pt
A15: 15 | B15: delta bonus
A16: 16 | B16: delta fanta pt
A17: 17
A18: 18
A19: 19
A20: 20
A21: 21
A22: 22
A23: 23
A24: 24
A25: 25
A26: 26
A27: 27
A28: 28
... A31: 31

Sheet GIOCATORI
D1: #VALUE!
A2: RUOLO | B2: NOME | C2: FANTASQ | D2: GOL | E2: ASSIST | F2: RIG OK | G2: RIG KO | H2: RIG PAR | I2: CLN SHT | J2: AMM | K2: ESP | L2: AUTGOL | M2: voto | N2: fvoto | O2: tot fvoto | P2: GOL SUBITI | Q2: partite giocate | R2: PARTITE DA TIT | S2: MEDIA FVOTO TIT | T2: TOT FVOTO TIT | W2: media voto | AB2: gol | AG2: ammonizioni | AL2: CLN SHEET | AQ2: RIGORI SEGNATI
A3: A | B3: Martinez L. | C3: =_xlfn.IFNA(_xlfn.XLOOKUP(B3,'[1]ROSE SQUADRE'!$N:$N,'[1]ROSE SQUADRE'!$O:$O),"") -> HERTHA VERNELLO | D3: =_xlfn.XLOOKUP($B3,'[1]Pivot Gioc'!$B:$B,'[1]Pivot Gioc'!$Q:$Q,"") -> 16 | E3: =_xlfn.XLOOKUP($B3,'[1]Pivot Gioc'!$B:$B,'[1]Pivot Gioc'!$N:$N,"") -> 5 | F3: =_xlfn.XLOOKUP($B3,'[1]Pivot Gioc'!$B:$B,'[1]Pivot Gioc'!$J:$J,"") -> 0 | G3: =_xlfn.XLOOKUP($B3,'[1]Pivot Gioc'!$B:$B,'[1]Pivot Gioc'!$I:$I,"") -> 0 | H3: =_xlfn.XLOOKUP($B3,'[1]Pivot Gioc'!$B:$B,'[1]Pivot Gioc'!$H:$H,"") -> 0 | I3: =_xlfn.XLOOKUP($B3,'[1]Pivot Gioc'!$B:$B,'[1]Pivot Gioc'!$P:$P,"") -> 0 | J3: =_xlfn.XLOOKUP($B3,'[1]Pivot Gioc'!$B:$B,'[1]Pivot Gioc'!$L:$L,"") -> 3 | K3: =_xlfn.XLOOKUP($B3,'[1]Pivot Gioc'!$B:$B,'[1]Pivot Gioc'!$M:$M,"") -> 0 | L3: =_xlfn.XLOOKUP($B3,'[1]Pivot Gioc'!$B:$B,'[1]Pivot Gioc'!$K:$K,"") -> 0 | M3: =_xlfn.XLOOKUP($B3,'[1]Pivot Gioc'!$B:$B,'[1]Pivot Gioc'!$C:$C,"") -> 6.4107143 | N3: =_xlfn.XLOOKUP($B3,'[1]Pivot Gioc'!$B:$B,'[1]Pivot Gioc'!$D:$D,"") -> 8.6428571 | O3: =_xlfn.XLOOKUP($B3,'[1]Pivot Gioc'!$B:$B,'[1]Pivot Gioc'!$E:$E,"") -> 242 | P3: =IF(_xlfn.XLOOKUP($B3,'[1]Pivot Gioc'!$B:$B,'[1]Pivot Gioc'!$G:$G,"")=0,"",_xlfn.XLOOKUP($B3,'[1]Pivot Gioc'!$B:$B,'[1]Pivot Gioc'!$G:$G)) | Q3: =_xlfn.XLOOKUP(B3,[1]!Tabella4[nome],[1]!Tabella4[PRES]) -> #REF! | R3: =_xlfn.XLOOKUP($B3,[1]!Tabella4[nome],[1]!Tabella4[LEGA TIT]) -> #REF! | S3: =IF(_xlfn.XLOOKUP($B3,'[1]Pivot Gioc'!$B:$B,'[1]Pivot Gioc'!$S:$S)="0,00","",_xlfn.XLOOKUP($B3,'[1]Pivot Gioc'!$B:$B,'[1]Pivot Gioc'!$S:$S)) -> 8.6428571 | T3: =IF(_xlfn.XLOOKUP($B3,'[1]Pivot Gioc'!$B:$B,'[1]Pivot Gioc'!$T:$T)=0,"",_xlfn.XLOOKUP($B3,'[1]Pivot Gioc'!$B:$B,'[1]Pivot Gioc'!$T:$T)) -> 242 | W3: {=INDEX(_xlfn._xlws.SORT($B$3:$N$508,12,-1),_xlfn.SEQUENCE(10),1)} -> Lukaku | X3: {=INDEX(_xlfn._xlws.SORT($B$3:$N$508,12,-1),_xlfn.SEQUENCE(10),12)} -> 7 | Y3: {=INDEX(_xlfn._xlws.SORT($B$3:$N$508,12,-1),_xlfn.SEQUENCE(10),2)} -> SAN GRIA | AB3: {=INDEX(_xlfn._xlws.SORT($B$3:$N$508,3,-1),_xlfn.SEQUENCE(20),1)} -> Martinez L. | AC3: {=INDEX(_xlfn._xlws.SORT($B$3:$N$508,3,-1),_xlfn.SEQUENCE(20),3)} -> 16 | AD3: {=INDEX(_xlfn._xlws.SORT($B$3:$N$508,3,-1),_xlfn.SEQUENCE(20),2)} -> HERTHA VERNELLO | AG3: {=INDEX(_xlfn._xlws.SORT($B$3:$N$508,9,-1),_xlfn.SEQUENCE(10),1)} -> Malinovskyi | AH3: {=INDEX(_xlfn._xlws.SORT($B$3:$N$508,9,-1),_xlfn.SEQUENCE(10),9)} -> 10 | AI3: {=INDEX(_xlfn._xlws.SORT($B$3:$N$508,9,-1),_xlfn.SEQUENCE(10),2)} -> HERTHA VERNELLO | AL3: {=INDEX(_xlfn._xlws.SORT($B$3:$N$508,8,-1),_xlfn.SEQUENCE(10),1)} -> Butez | AM3: {=INDEX(_xlfn._xlws.SORT($B$3:$N$508,8,-1),_xlfn.SEQUENCE(10),8)} -> 18 | AN3: {=INDEX(_xlfn._xlws.SORT($B$3:$N$508,8,-1),_xlfn.SEQUENCE(10),2)} -> SAN GRIA | AQ3: {=INDEX(_xlfn._xlws.SORT($B$3:$N$508,5,-1),_xlfn.SEQUENCE(10),1)} -> Vlasic | AR3: {=INDEX(_xlfn._xlws.SORT($B$3:$N$508,5,-1),_xlfn.SEQUENCE(10),5)} -> 5 | AS3: {=INDEX(_xlfn._xlws.SORT($B$3:$N$508,5,-1),_xlfn.SEQUENCE(10),2)} -> PESCICULINI FC
A4: P | B4: Malen | C4: =_xlfn.IFNA(_xlfn.XLOOKUP(B4,'[1]ROSE SQUADRE'!$N:$N,'[1]ROSE SQUADRE'!$O:$O),"") -> APPAREGGIATO | D4: =_xlfn.XLOOKUP($B4,'[1]Pivot Gioc'!$B:$B,'[1]Pivot Gioc'!$Q:$Q,"") -> 14 | E4: =_xlfn.XLOOKUP($B4,'[1]Pivot Gioc'!$B:$B,'[1]Pivot Gioc'!$N:$N,"") -> 2 | F4: =_xlfn.XLOOKUP($B4,'[1]Pivot Gioc'!$B:$B,'[1]Pivot Gioc'!$J:$J,"") -> 3 | G4: =_xlfn.XLOOKUP($B4,'[1]Pivot Gioc'!$B:$B,'[1]Pivot Gioc'!$I:$I,"") -> 1 | H4: =_xlfn.XLOOKUP($B4,'[1]Pivot Gioc'!$B:$B,'[1]Pivot Gioc'!$H:$H,"") -> 0 | I4: =_xlfn.XLOOKUP($B4,'[1]Pivot Gioc'!$B:$B,'[1]Pivot Gioc'!$P:$P,"") -> 0 | J4: =_xlfn.XLOOKUP($B4,'[1]Pivot Gioc'!$B:$B,'[1]Pivot Gioc'!$L:$L,"") -> 1 | K4: =_xlfn.XLOOKUP($B4,'[1]Pivot Gioc'!$B:$B,'[1]Pivot Gioc'!$M:$M,"") -> 0 | L4: =_xlfn.XLOOKUP($B4,'[1]Pivot Gioc'!$B:$B,'[1]Pivot Gioc'!$K:$K,"") -> 0 | M4: =_xlfn.XLOOKUP($B4,'[1]Pivot Gioc'!$B:$B,'[1]Pivot Gioc'!$C:$C,"") -> 6.7222222 | N4: =_xlfn.XLOOKUP($B4,'[1]Pivot Gioc'!$B:$B,'[1]Pivot Gioc'!$D:$D,"") -> 9.3055556 | O4: =_xlfn.XLOOKUP($B4,'[1]Pivot Gioc'!$B:$B,'[1]Pivot Gioc'!$E:$E,"") -> 167.5 | P4: =IF(_xlfn.XLOOKUP($B4,'[1]Pivot Gioc'!$B:$B,'[1]Pivot Gioc'!$G:$G,"")=0,"",_xlfn.XLOOKUP($B4,'[1]Pivot Gioc'!$B:$B,'[1]Pivot Gioc'!$G:$G)) | Q4: =_xlfn.XLOOKUP(B4,[1]!Tabella4[nome],[1]!Tabella4[PRES]) -> #REF! | R4: =_xlfn.XLOOKUP(B4,[1]!Tabella4[nome],[1]!Tabella4[LEGA TIT]) -> #REF! | S4: =IF(_xlfn.XLOOKUP($B4,'[1]Pivot Gioc'!$B:$B,'[1]Pivot Gioc'!$S:$S)="0,00","",_xlfn.XLOOKUP($B4,'[1]Pivot Gioc'!$B:$B,'[1]Pivot Gioc'!$S:$S)) -> 9.7 | T4: =IF(_xlfn.XLOOKUP($B4,'[1]Pivot Gioc'!$B:$B,'[1]Pivot Gioc'!$T:$T)=0,"",_xlfn.XLOOKUP($B4,'[1]Pivot Gioc'!$B:$B,'[1]Pivot Gioc'!$T:$T)) -> 145.5 | W4: Rinaldi | X4: 7 | AB4: Malen | AC4: 14 | AD4: APPAREGGIATO | AG4: Caracciolo A. | AH4: 10 | AL4: Svilar | AM4: 16 | AN4: HERTHA VERNELLO | AQ4: Nkunku | AR4: 5 | AS4: PARTIZAN DEGRADO
A5: C | B5: Douvikas | C5: =_xlfn.IFNA(_xlfn.XLOOKUP(B5,'[1]ROSE SQUADRE'!$N:$N,'[1]ROSE SQUADRE'!$O:$O),"") -> AC ASPARAGHESE | D5: =_xlfn.XLOOKUP($B5,'[1]Pivot Gioc'!$B:$B,'[1]Pivot Gioc'!$Q:$Q,"") -> 13 | E5: =_xlfn.XLOOKUP($B5,'[1]Pivot Gioc'!$B:$B,'[1]Pivot Gioc'!$N:$N,"") -> 1 | F5: =_xlfn.XLOOKUP($B5,'[1]Pivot Gioc'!$B:$B,'[1]Pivot Gioc'!$J:$J,"") -> 1 | G5: =_xlfn.XLOOKUP($B5,'[1]Pivot Gioc'!$B:$B,'[1]Pivot Gioc'!$I:$I,"") -> 0 | H5: =_xlfn.XLOOKUP($B5,'[1]Pivot Gioc'!$B:$B,'[1]Pivot Gioc'!$H:$H,"") -> 0 | I5: =_xlfn.XLOOKUP($B5,'[1]Pivot Gioc'!$B:$B,'[1]Pivot Gioc'!$P:$P,"") -> 0 | J5: =_xlfn.XLOOKUP($B5,'[1]Pivot Gioc'!$B:$B,'[1]Pivot Gioc'!$L:$L,"") -> 0 | K5: =_xlfn.XLOOKUP($B5,'[1]Pivot Gioc'!$B:$B,'[1]Pivot Gioc'!$M:$M,"") -> 0 | L5: =_xlfn.XLOOKUP($B5,'[1]Pivot Gioc'!$B:$B,'[1]Pivot Gioc'!$K:$K,"") -> 0 | M5: =_xlfn.XLOOKUP($B5,'[1]Pivot Gioc'!$B:$B,'[1]Pivot Gioc'!$C:$C,"") -> 6.1764706 | N5: =_xlfn.XLOOKUP($B5,'[1]Pivot Gioc'!$B:$B,'[1]Pivot Gioc'!$D:$D,"") -> 7.5 | O5: =_xlfn.XLOOKUP($B5,'[1]Pivot Gioc'!$B:$B,'[1]Pivot Gioc'!$E:$E,"") -> 255 | P5: =IF(_xlfn.XLOOKUP($B5,'[1]Pivot Gioc'!$B:$B,'[1]Pivot Gioc'!$G:$G,"")=0,"",_xlfn.XLOOKUP($B5,'[1]Pivot Gioc'!$B:$B,'[1]Pivot Gioc'!$G:$G)) | Q5: =_xlfn.XLOOKUP(B5,[1]!Tabella4[nome],[1]!Tabella4[PRES]) -> #REF! | R5: =_xlfn.XLOOKUP(B5,[1]!Tabella4[nome],[1]!Tabella4[LEGA TIT]) -> #REF! | S5: =IF(_xlfn.XLOOKUP($B5,'[1]Pivot Gioc'!$B:$B,'[1]Pivot Gioc'!$S:$S)="0,00","",_xlfn.XLOOKUP($B5,'[1]Pivot Gioc'!$B:$B,'[1]Pivot Gioc'!$S:$S)) -> 7.7592593 | T5: =IF(_xlfn.XLOOKUP($B5,'[1]Pivot Gioc'!$B:$B,'[1]Pivot Gioc'!$T:$T)=0,"",_xlfn.XLOOKUP($B5,'[1]Pivot Gioc'!$B:$B,'[1]Pivot Gioc'!$T:$T)) -> 209.5 | W5: Malen | X5: 6.7222222 | Y5: APPAREGGIATO | AB5: Douvikas | AC5: 13 | AD5: AC ASPARAGHESE | AG5: Ramon | AH5: 10 | AI5: APPAREGGIATO | AL5: Sommer | AM5: 15 | AN5: SESTO ASENSIO | AQ5: Orsolini | AR5: 4 | AS5: PARTIZAN DEGRADO
A6: C | B6: Hojlund | C6: =_xlfn.IFNA(_xlfn.XLOOKUP(B6,'[1]ROSE SQUADRE'!$N:$N,'[1]ROSE SQUADRE'!$O:$O),"") -> SAN GRIA | D6: =_xlfn.XLOOKUP($B6,'[1]Pivot Gioc'!$B:$B,'[1]Pivot Gioc'!$Q:$Q,"") -> 12 | E6: =_xlfn.XLOOKUP($B6,'[1]Pivot Gioc'!$B:$B,'[1]Pivot Gioc'!$N:$N,"") -> 5 | F6: =_xlfn.XLOOKUP($B6,'[1]Pivot Gioc'!$B:$B,'[1]Pivot Gioc'!$J:$J,"") -> 1 | G6: =_xlfn.XLOOKUP($B6,'[1]Pivot Gioc'!$B:$B,'[1]Pivot Gioc'!$I:$I,"") -> 0 | H6: =_xlfn.XLOOKUP($B6,'[1]Pivot Gioc'!$B:$B,'[1]Pivot Gioc'!$H:$H,"") -> 0 | I6: =_xlfn.XLOOKUP($B6,'[1]Pivot Gioc'!$B:$B,'[1]Pivot Gioc'!$P:$P,"") -> 0 | J6: =_xlfn.XLOOKUP($B6,'[1]Pivot Gioc'!$B:$B,'[1]Pivot Gioc'!$L:$L,"") -> 1 | K6: =_xlfn.XLOOKUP($B6,'[1]Pivot Gioc'!$B:$B,'[1]Pivot Gioc'!$M:$M,"") -> 0 | L6: =_xlfn.XLOOKUP($B6,'[1]Pivot Gioc'!$B:$B,'[1]Pivot Gioc'!$K:$K,"") -> 0 | M6: =_xlfn.XLOOKUP($B6,'[1]Pivot Gioc'!$B:$B,'[1]Pivot Gioc'!$C:$C,"") -> 6.2121212 | N6: =_xlfn.XLOOKUP($B6,'[1]Pivot Gioc'!$B:$B,'[1]Pivot Gioc'!$D:$D,"") -> 7.6212121 | O6: =_xlfn.XLOOKUP($B6,'[1]Pivot Gioc'!$B:$B,'[1]Pivot Gioc'!$E:$E,"") -> 251.5 | P6: =IF(_xlfn.XLOOKUP($B6,'[1]Pivot Gioc'!$B:$B,'[1]Pivot Gioc'!$G:$G,"")=0,"",_xlfn.XLOOKUP($B6,'[1]Pivot Gioc'!$B:$B,'[1]Pivot Gioc'!$G:$G)) | Q6: =_xlfn.XLOOKUP(B6,[1]!Tabella4[nome],[1]!Tabella4[PRES]) -> #REF! | R6: =_xlfn.XLOOKUP(B6,[1]!Tabella4[nome],[1]!Tabella4[LEGA TIT]) -> #REF! | S6: =IF(_xlfn.XLOOKUP($B6,'[1]Pivot Gioc'!$B:$B,'[1]Pivot Gioc'!$S:$S)="0,00","",_xlfn.XLOOKUP($B6,'[1]Pivot Gioc'!$B:$B,'[1]Pivot Gioc'!$S:$S)) -> 7.5 | T6: =IF(_xlfn.XLOOKUP($B6,'[1]Pivot Gioc'!$B:$B,'[1]Pivot Gioc'!$T:$T)=0,"",_xlfn.XLOOKUP($B6,'[1]Pivot Gioc'!$B:$B,'[1]Pivot Gioc'!$T:$T)) -> 240 | W6: Dimarco | X6: 6.6212121 | Y6: ATL IMPROVVISATO | AB6: Hojlund | AC6: 12 | AD6: SAN GRIA | AG6: Gagliardini | AH6: 10 | AL6: Maignan | AM6: 13 | AN6: APPAREGGIATO | AQ6: Calhanoglu | AR6: 4 | AS6: SAN GRIA
B7: Paz N. | C7: =_xlfn.IFNA(_xlfn.XLOOKUP(B7,'[1]ROSE SQUADRE'!$N:$N,'[1]ROSE SQUADRE'!$O:$O),"") -> AC ASPARAGHESE | D7: =_xlfn.XLOOKUP($B7,'[1]Pivot Gioc'!$B:$B,'[1]Pivot Gioc'!$Q:$Q,"") -> 11 | E7: =_xlfn.XLOOKUP($B7,'[1]Pivot Gioc'!$B:$B,'[1]Pivot Gioc'!$N:$N,"") -> 4 | F7: =_xlfn.XLOOKUP($B7,'[1]Pivot Gioc'!$B:$B,'[1]Pivot Gioc'!$J:$J,"") -> 0 | G7: =_xlfn.XLOOKUP($B7,'[1]Pivot Gioc'!$B:$B,'[1]Pivot Gioc'!$I:$I,"") -> 2 | H7: =_xlfn.XLOOKUP($B7,'[1]Pivot Gioc'!$B:$B,'[1]Pivot Gioc'!$H:$H,"") -> 0 | I7: =_xlfn.XLOOKUP($B7,'[1]Pivot Gioc'!$B:$B,'[1]Pivot Gioc'!$P:$P,"") -> 0 | J7: =_xlfn.XLOOKUP($B7,'[1]Pivot Gioc'!$B:$B,'[1]Pivot Gioc'!$L:$L,"") -> 4 | K7: =_xlfn.XLOOKUP($B7,'[1]Pivot Gioc'!$B:$B,'[1]Pivot Gioc'!$M:$M,"") -> 0 | L7: =_xlfn.XLOOKUP($B7,'[1]Pivot Gioc'!$B:$B,'[1]Pivot Gioc'!$K:$K,"") -> 0 | M7: =_xlfn.XLOOKUP($B7,'[1]Pivot Gioc'!$B:$B,'[1]Pivot Gioc'!$C:$C,"") -> 6.3333333 | N7: =_xlfn.XLOOKUP($B7,'[1]Pivot Gioc'!$B:$B,'[1]Pivot Gioc'!$D:$D,"") -> 7.2424242 | O7: =_xlfn.XLOOKUP($B7,'[1]Pivot Gioc'!$B:$B,'[1]Pivot Gioc'!$E:$E,"") -> 239 | P7: =IF(_xlfn.XLOOKUP($B7,'[1]Pivot Gioc'!$B:$B,'[1]Pivot Gioc'!$G:$G,"")=0,"",_xlfn.XLOOKUP($B7,'[1]Pivot Gioc'!$B:$B,'[1]Pivot Gioc'!$G:$G)) | Q7: =_xlfn.XLOOKUP(B7,[1]!Tabella4[nome],[1]!Tabella4[PRES]) -> #REF! | R7: =_xlfn.XLOOKUP(B7,[1]!Tabella4[nome],[1]!Tabella4[LEGA TIT]) -> #REF! | S7: =IF(_xlfn.XLOOKUP($B7,'[1]Pivot Gioc'!$B:$B,'[1]Pivot Gioc'!$S:$S)="0,00","",_xlfn.XLOOKUP($B7,'[1]Pivot Gioc'!$B:$B,'[1]Pivot Gioc'!$S:$S)) -> 7.2424242 | T7: =IF(_xlfn.XLOOKUP($B7,'[1]Pivot Gioc'!$B:$B,'[1]Pivot Gioc'!$T:$T)=0,"",_xlfn.XLOOKUP($B7,'[1]Pivot Gioc'!$B:$B,'[1]Pivot Gioc'!$T:$T)) -> 239 | W7: Calhanoglu | X7: 6.5952381 | Y7: SAN GRIA | AB7: Paz N. | AC7: 11 | AD7: AC ASPARAGHESE | AG7: Ramadani | AH7: 10 | AL7: Carnesecchi | AM7: 13 | AN7: SAN GRIA | AQ7: Da Cunha | AR7: 4 | AS7: PARTIZAN DEGRADO
B8: Simeone | C8: =_xlfn.IFNA(_xlfn.XLOOKUP(B8,'[1]ROSE SQUADRE'!$N:$N,'[1]ROSE SQUADRE'!$O:$O),"") -> APPAREGGIATO | D8: =_xlfn.XLOOKUP($B8,'[1]Pivot Gioc'!$B:$B,'[1]Pivot Gioc'!$Q:$Q,"") -> 11 | E8: =_xlfn.XLOOKUP($B8,'[1]Pivot Gioc'!$B:$B,'[1]Pivot Gioc'!$N:$N,"") -> 0 | F8: =_xlfn.XLOOKUP($B8,'[1]Pivot Gioc'!$B:$B,'[1]Pivot Gioc'!$J:$J,"") -> 0 | G8: =_xlfn.XLOOKUP($B8,'[1]Pivot Gioc'!$B:$B,'[1]Pivot Gioc'!$I:$I,"") -> 0 | H8: =_xlfn.XLOOKUP($B8,'[1]Pivot Gioc'!$B:$B,'[1]Pivot Gioc'!$H:$H,"") -> 0 | I8: =_xlfn.XLOOKUP($B8,'[1]Pivot Gioc'!$B:$B,'[1]Pivot Gioc'!$P:$P,"") -> 0 | J8: =_xlfn.XLOOKUP($B8,'[1]Pivot Gioc'!$B:$B,'[1]Pivot Gioc'!$L:$L,"") -> 1 | K8: =_xlfn.XLOOKUP($B8,'[1]Pivot Gioc'!$B:$B,'[1]Pivot Gioc'!$M:$M,"") -> 0 | L8: =_xlfn.XLOOKUP($B8,'[1]Pivot Gioc'!$B:$B,'[1]Pivot Gioc'!$K:$K,"") -> 0 | M8: =_xlfn.XLOOKUP($B8,'[1]Pivot Gioc'!$B:$B,'[1]Pivot Gioc'!$C:$C,"") -> 6.1 | N8: =_xlfn.XLOOKUP($B8,'[1]Pivot Gioc'!$B:$B,'[1]Pivot Gioc'!$D:$D,"") -> 7.3166667 | O8: =_xlfn.XLOOKUP($B8,'[1]Pivot Gioc'!$B:$B,'[1]Pivot Gioc'!$E:$E,"") -> 219.5 | P8: =IF(_xlfn.XLOOKUP($B8,'[1]Pivot Gioc'!$B:$B,'[1]Pivot Gioc'!$G:$G,"")=0,"",_xlfn.XLOOKUP($B8,'[1]Pivot Gioc'!$B:$B,'[1]Pivot Gioc'!$G:$G)) | Q8: =_xlfn.XLOOKUP(B8,[1]!Tabella4[nome],[1]!Tabella4[PRES]) -> #REF! | R8: =_xlfn.XLOOKUP(B8,[1]!Tabella4[nome],[1]!Tabella4[LEGA TIT]) -> #REF! | S8: =IF(_xlfn.XLOOKUP($B8,'[1]Pivot Gioc'!$B:$B,'[1]Pivot Gioc'!$S:$S)="0,00","",_xlfn.XLOOKUP($B8,'[1]Pivot Gioc'!$B:$B,'[1]Pivot Gioc'!$S:$S)) -> 7.04 | T8: =IF(_xlfn.XLOOKUP($B8,'[1]Pivot Gioc'!$B:$B,'[1]Pivot Gioc'!$T:$T)=0,"",_xlfn.XLOOKUP($B8,'[1]Pivot Gioc'!$B:$B,'[1]Pivot Gioc'!$T:$T)) -> 176 | W8: Modric | X8: 6.4516129 | Y8: SESTO ASENSIO | AB8: Simeone | AC8: 11 | AD8: APPAREGGIATO | AG8: Pongracic | AH8: 10 | AL8: Di Gregorio | AM8: 12 | AN8: ATL IMPROVVISATO | AQ8: Malen | AR8: 3 | AS8: APPAREGGIATO
B9: Thuram | C9: =_xlfn.IFNA(_xlfn.XLOOKUP(B9,'[1]ROSE SQUADRE'!$N:$N,'[1]ROSE SQUADRE'!$O:$O),"") -> PESCICULINI FC | D9: =_xlfn.XLOOKUP($B9,'[1]Pivot Gioc'!$B:$B,'[1]Pivot Gioc'!$Q:$Q,"") -> 11 | E9: =_xlfn.XLOOKUP($B9,'[1]Pivot Gioc'!$B:$B,'[1]Pivot Gioc'!$N:$N,"") -> 5 | F9: =_xlfn.XLOOKUP($B9,'[1]Pivot Gioc'!$B:$B,'[1]Pivot Gioc'!$J:$J,"") -> 0 | G9: =_xlfn.XLOOKUP($B9,'[1]Pivot Gioc'!$B:$B,'[1]Pivot Gioc'!$I:$I,"") -> 0 | H9: =_xlfn.XLOOKUP($B9,'[1]Pivot Gioc'!$B:$B,'[1]Pivot Gioc'!$H:$H,"") -> 0 | I9: =_xlfn.XLOOKUP($B9,'[1]Pivot Gioc'!$B:$B,'[1]Pivot Gioc'!$P:$P,"") -> 0 | J9: =_xlfn.XLOOKUP($B9,'[1]Pivot Gioc'!$B:$B,'[1]Pivot Gioc'!$L:$L,"") -> 2 | K9: =_xlfn.XLOOKUP($B9,'[1]Pivot Gioc'!$B:$B,'[1]Pivot Gioc'!$M:$M,"") -> 0 | L9: =_xlfn.XLOOKUP($B9,'[1]Pivot Gioc'!$B:$B,'[1]Pivot Gioc'!$K:$K,"") -> 0 | M9: =_xlfn.XLOOKUP($B9,'[1]Pivot Gioc'!$B:$B,'[1]Pivot Gioc'!$C:$C,"") -> 6.3888889 | N9: =_xlfn.XLOOKUP($B9,'[1]Pivot Gioc'!$B:$B,'[1]Pivot Gioc'!$D:$D,"") -> 7.8333333 | O9: =_xlfn.XLOOKUP($B9,'[1]Pivot Gioc'!$B:$B,'[1]Pivot Gioc'!$E:$E,"") -> 211.5 | P9: =IF(_xlfn.XLOOKUP($B9,'[1]Pivot Gioc'!$B:$B,'[1]Pivot Gioc'!$G:$G,"")=0,"",_xlfn.XLOOKUP($B9,'[1]Pivot Gioc'!$B:$B,'[1]Pivot Gioc'!$G:$G)) | Q9: =_xlfn.XLOOKUP(B9,[1]!Tabella4[nome],[1]!Tabella4[PRES]) -> #REF! | R9: =_xlfn.XLOOKUP(B9,[1]!Tabella4[nome],[1]!Tabella4[LEGA TIT]) -> #REF! | S9: =IF(_xlfn.XLOOKUP($B9,'[1]Pivot Gioc'!$B:$B,'[1]Pivot Gioc'!$S:$S)="0,00","",_xlfn.XLOOKUP($B9,'[1]Pivot Gioc'!$B:$B,'[1]Pivot Gioc'!$S:$S)) -> 7.8333333 | T9: =IF(_xlfn.XLOOKUP($B9,'[1]Pivot Gioc'!$B:$B,'[1]Pivot Gioc'!$T:$T)=0,"",_xlfn.XLOOKUP($B9,'[1]Pivot Gioc'!$B:$B,'[1]Pivot Gioc'!$T:$T)) -> 211.5 | W9: Martinez L. | X9: 6.4107143 | Y9: HERTHA VERNELLO | AB9: Thuram | AC9: 11 | AD9: PESCICULINI FC | AG9: Thorstvedt | AH9: 9 | AI9: AC ASPARAGHESE | AL9: Audero | AM9: 11 | AQ9: Bonazzoli | AR9: 3 | AS9: APPAREGGIATO
A10: C | B10: Krstovic | C10: =_xlfn.IFNA(_xlfn.XLOOKUP(B10,'[1]ROSE SQUADRE'!$N:$N,'[1]ROSE SQUADRE'!$O:$O),"") -> PARTIZAN DEGRADO | D10: =_xlfn.XLOOKUP($B10,'[1]Pivot Gioc'!$B:$B,'[1]Pivot Gioc'!$Q:$Q,"") -> 10 | E10: =_xlfn.XLOOKUP($B10,'[1]Pivot Gioc'!$B:$B,'[1]Pivot Gioc'!$N:$N,"") -> 4 | F10: =_xlfn.XLOOKUP($B10,'[1]Pivot Gioc'!$B:$B,'[1]Pivot Gioc'!$J:$J,"") -> 0 | G10: =_xlfn.XLOOKUP($B10,'[1]Pivot Gioc'!$B:$B,'[1]Pivot Gioc'!$I:$I,"") -> 0 | H10: =_xlfn.XLOOKUP($B10,'[1]Pivot Gioc'!$B:$B,'[1]Pivot Gioc'!$H:$H,"") -> 0 | I10: =_xlfn.XLOOKUP($B10,'[1]Pivot Gioc'!$B:$B,'[1]Pivot Gioc'!$P:$P,"") -> 0 | J10: =_xlfn.XLOOKUP($B10,'[1]Pivot Gioc'!$B:$B,'[1]Pivot Gioc'!$L:$L,"") -> 4 | K10: =_xlfn.XLOOKUP($B10,'[1]Pivot Gioc'!$B:$B,'[1]Pivot Gioc'!$M:$M,"") -> 0 | L10: =_xlfn.XLOOKUP($B10,'[1]Pivot Gioc'!$B:$B,'[1]Pivot Gioc'!$K:$K,"") -> 0 | M10: =_xlfn.XLOOKUP($B10,'[1]Pivot Gioc'!$B:$B,'[1]Pivot Gioc'!$C:$C,"") -> 6.1666667 | N10: =_xlfn.XLOOKUP($B10,'[1]Pivot Gioc'!$B:$B,'[1]Pivot Gioc'!$D:$D,"") -> 7.3 | O10: =_xlfn.XLOOKUP($B10,'[1]Pivot Gioc'!$B:$B,'[1]Pivot Gioc'!$E:$E,"") -> 219 | P10: =IF(_xlfn.XLOOKUP($B10,'[1]Pivot Gioc'!$B:$B,'[1]Pivot Gioc'!$G:$G,"")=0,"",_xlfn.XLOOKUP($B10,'[1]Pivot Gioc'!$B:$B,'[1]Pivot Gioc'!$G:$G)) | Q10: =_xlfn.XLOOKUP(B10,[1]!Tabella4[nome],[1]!Tabella4[PRES]) -> #REF! | R10: =_xlfn.XLOOKUP(B10,[1]!Tabella4[nome],[1]!Tabella4[LEGA TIT]) -> #REF! | S10: =IF(_xlfn.XLOOKUP($B10,'[1]Pivot Gioc'!$B:$B,'[1]Pivot Gioc'!$S:$S)="0,00","",_xlfn.XLOOKUP($B10,'[1]Pivot Gioc'!$B:$B,'[1]Pivot Gioc'!$S:$S)) -> 7.4782609 | T10: =IF(_xlfn.XLOOKUP($B10,'[1]Pivot Gioc'!$B:$B,'[1]Pivot Gioc'!$T:$T)=0,"",_xlfn.XLOOKUP($B10,'[1]Pivot Gioc'!$B:$B,'[1]Pivot Gioc'!$T:$T)) -> 172 | W10: Thuram | X10: 6.3888889 | Y10: PESCICULINI FC | AB10: Krstovic | AC10: 10 | AD10: PARTIZAN DEGRADO | AG10: Hermoso | AH10: 9 | AI10: PESCICULINI FC | AL10: Provedel | AM10: 11 | AN10: AC ASPARAGHESE | AQ10: Davis K. | AR10: 3 | AS10: PARTIZAN DEGRADO
B11: Yildiz | C11: =_xlfn.IFNA(_xlfn.XLOOKUP(B11,'[1]ROSE SQUADRE'!$N:$N,'[1]ROSE SQUADRE'!$O:$O),"") -> SESTO ASENSIO | D11: =_xlfn.XLOOKUP($B11,'[1]Pivot Gioc'!$B:$B,'[1]Pivot Gioc'!$Q:$Q,"") -> 10 | E11: =_xlfn.XLOOKUP($B11,'[1]Pivot Gioc'!$B:$B,'[1]Pivot Gioc'!$N:$N,"") -> 4 | F11: =_xlfn.XLOOKUP($B11,'[1]Pivot Gioc'!$B:$B,'[1]Pivot Gioc'!$J:$J,"") -> 1 | G11: =_xlfn.XLOOKUP($B11,'[1]Pivot Gioc'!$B:$B,'[1]Pivot Gioc'!$I:$I,"") -> 1 | H11: =_xlfn.XLOOKUP($B11,'[1]Pivot Gioc'!$B:$B,'[1]Pivot Gioc'!$H:$H,"") -> 0 | I11: =_xlfn.XLOOKUP($B11,'[1]Pivot Gioc'!$B:$B,'[1]Pivot Gioc'!$P:$P,"") -> 0 | J11: =_xlfn.XLOOKUP($B11,'[1]Pivot Gioc'!$B:$B,'[1]Pivot Gioc'!$L:$L,"") -> 2 | K11: =_xlfn.XLOOKUP($B11,'[1]Pivot Gioc'!$B:$B,'[1]Pivot Gioc'!$M:$M,"") -> 0 | L11: =_xlfn.XLOOKUP($B11,'[1]Pivot Gioc'!$B:$B,'[1]Pivot Gioc'!$K:$K,"") -> 0 | M11: =_xlfn.XLOOKUP($B11,'[1]Pivot Gioc'!$B:$B,'[1]Pivot Gioc'!$C:$C,"") -> 6.3636364 | N11: =_xlfn.XLOOKUP($B11,'[1]Pivot Gioc'!$B:$B,'[1]Pivot Gioc'!$D:$D,"") -> 7.3030303 | O11: =_xlfn.XLOOKUP($B11,'[1]Pivot Gioc'!$B:$B,'[1]Pivot Gioc'!$E:$E,"") -> 241 | P11: =IF(_xlfn.XLOOKUP($B11,'[1]Pivot Gioc'!$B:$B,'[1]Pivot Gioc'!$G:$G,"")=0,"",_xlfn.XLOOKUP($B11,'[1]Pivot Gioc'!$B:$B,'[1]Pivot Gioc'!$G:$G)) | Q11: =_xlfn.XLOOKUP(B11,[1]!Tabella4[nome],[1]!Tabella4[PRES]) -> #REF! | R11: =_xlfn.XLOOKUP(B11,[1]!Tabella4[nome],[1]!Tabella4[LEGA TIT]) -> #REF! | S11: =IF(_xlfn.XLOOKUP($B11,'[1]Pivot Gioc'!$B:$B,'[1]Pivot Gioc'!$S:$S)="0,00","",_xlfn.XLOOKUP($B11,'[1]Pivot Gioc'!$B:$B,'[1]Pivot Gioc'!$S:$S)) -> 7.3030303 | T11: =IF(_xlfn.XLOOKUP($B11,'[1]Pivot Gioc'!$B:$B,'[1]Pivot Gioc'!$T:$T)=0,"",_xlfn.XLOOKUP($B11,'[1]Pivot Gioc'!$B:$B,'[1]Pivot Gioc'!$T:$T)) -> 241 | W11: Falcone | X11: 6.3888889 | Y11: AC ASPARAGHESE | AB11: Yildiz | AC11: 10 | AD11: SESTO ASENSIO | AG11: Akpa Akpro | AH11: 9 | AL11: Okoye | AM11: 11 | AN11: PESCICULINI FC | AQ11: Malinovskyi | AR11: 3 | AS11: HERTHA VERNELLO
B12: Scamacca | C12: =_xlfn.IFNA(_xlfn.XLOOKUP(B12,'[1]ROSE SQUADRE'!$N:$N,'[1]ROSE SQUADRE'!$O:$O),"") -> AC ASPARAGHESE | D12: =_xlfn.XLOOKUP($B12,'[1]Pivot Gioc'!$B:$B,'[1]Pivot Gioc'!$Q:$Q,"") -> 9 | E12: =_xlfn.XLOOKUP($B12,'[1]Pivot Gioc'!$B:$B,'[1]Pivot Gioc'!$N:$N,"") -> 1 | F12: =_xlfn.XLOOKUP($B12,'[1]Pivot Gioc'!$B:$B,'[1]Pivot Gioc'!$J:$J,"") -> 2 | G12: =_xlfn.XLOOKUP($B12,'[1]Pivot Gioc'!$B:$B,'[1]Pivot Gioc'!$I:$I,"") -> 0 | H12: =_xlfn.XLOOKUP($B12,'[1]Pivot Gioc'!$B:$B,'[1]Pivot Gioc'!$H:$H,"") -> 0 | I12: =_xlfn.XLOOKUP($B12,'[1]Pivot Gioc'!$B:$B,'[1]Pivot Gioc'!$P:$P,"") -> 0 | J12: =_xlfn.XLOOKUP($B12,'[1]Pivot Gioc'!$B:$B,'[1]Pivot Gioc'!$L:$L,"") -> 2 | K12: =_xlfn.XLOOKUP($B12,'[1]Pivot Gioc'!$B:$B,'[1]Pivot Gioc'!$M:$M,"") -> 0 | L12: =_xlfn.XLOOKUP($B12,'[1]Pivot Gioc'!$B:$B,'[1]Pivot Gioc'!$K:$K,"") -> 0 | M12: =_xlfn.XLOOKUP($B12,'[1]Pivot Gioc'!$B:$B,'[1]Pivot Gioc'!$C:$C,"") -> 6.15 | N12: =_xlfn.XLOOKUP($B12,'[1]Pivot Gioc'!$B:$B,'[1]Pivot Gioc'!$D:$D,"") -> 7.6 | O12: =_xlfn.XLOOKUP($B12,'[1]Pivot Gioc'!$B:$B,'[1]Pivot Gioc'!$E:$E,"") -> 152 | P12: =IF(_xlfn.XLOOKUP($B12,'[1]Pivot Gioc'!$B:$B,'[1]Pivot Gioc'!$G:$G,"")=0,"",_xlfn.XLOOKUP($B12,'[1]Pivot Gioc'!$B:$B,'[1]Pivot Gioc'!$G:$G)) | Q12: =_xlfn.XLOOKUP(B12,[1]!Tabella4[nome],[1]!Tabella4[PRES]) -> #REF! | R12: =_xlfn.XLOOKUP(B12,[1]!Tabella4[nome],[1]!Tabella4[LEGA TIT]) -> #REF! | S12: =IF(_xlfn.XLOOKUP($B12,'[1]Pivot Gioc'!$B:$B,'[1]Pivot Gioc'!$S:$S)="0,00","",_xlfn.XLOOKUP($B12,'[1]Pivot Gioc'!$B:$B,'[1]Pivot Gioc'!$S:$S)) -> 7.8214286 | T12: =IF(_xlfn.XLOOKUP($B12,'[1]Pivot Gioc'!$B:$B,'[1]Pivot Gioc'!$T:$T)=0,"",_xlfn.XLOOKUP($B12,'[1]Pivot Gioc'!$B:$B,'[1]Pivot Gioc'!$T:$T)) -> 109.5 | W12: Silvestri | X12: 6.375 | AB12: Scamacca | AC12: 9 | AD12: AC ASPARAGHESE | AG12: Locatelli | AH12: 9 | AI12: ATL IMPROVVISATO | AL12: Milinkovic-Savic V. | AM12: 11 | AN12: SESTO ASENSIO | AQ12: Gudmundsson A. | AR12: 3 | AS12: APPAREGGIATO
A13: D | B13: Bonazzoli | C13: =_xlfn.IFNA(_xlfn.XLOOKUP(B13,'[1]ROSE SQUADRE'!$N:$N,'[1]ROSE SQUADRE'!$O:$O),"") -> APPAREGGIATO | D13: =_xlfn.XLOOKUP($B13,'[1]Pivot Gioc'!$B:$B,'[1]Pivot Gioc'!$Q:$Q,"") -> 9 | E13: =_xlfn.XLOOKUP($B13,'[1]Pivot Gioc'!$B:$B,'[1]Pivot Gioc'!$N:$N,"") -> 2 | F13: =_xlfn.XLOOKUP($B13,'[1]Pivot Gioc'!$B:$B,'[1]Pivot Gioc'!$J:$J,"") -> 3 | G13: =_xlfn.XLOOKUP($B13,'[1]Pivot Gioc'!$B:$B,'[1]Pivot Gioc'!$I:$I,"") -> 0 | H13: =_xlfn.XLOOKUP($B13,'[1]Pivot Gioc'!$B:$B,'[1]Pivot Gioc'!$H:$H,"") -> 0 | I13: =_xlfn.XLOOKUP($B13,'[1]Pivot Gioc'!$B:$B,'[1]Pivot Gioc'!$P:$P,"") -> 0 | J13: =_xlfn.XLOOKUP($B13,'[1]Pivot Gioc'!$B:$B,'[1]Pivot Gioc'!$L:$L,"") -> 4 | K13: =_xlfn.XLOOKUP($B13,'[1]Pivot Gioc'!$B:$B,'[1]Pivot Gioc'!$M:$M,"") -> 0 | L13: =_xlfn.XLOOKUP($B13,'[1]Pivot Gioc'!$B:$B,'[1]Pivot Gioc'!$K:$K,"") -> 0 | M13: =_xlfn.XLOOKUP($B13,'[1]Pivot Gioc'!$B:$B,'[1]Pivot Gioc'!$C:$C,"") -> 6.1176471 | N13: =_xlfn.XLOOKUP($B13,'[1]Pivot Gioc'!$B:$B,'[1]Pivot Gioc'!$D:$D,"") -> 6.9411765 | O13: =_xlfn.XLOOKUP($B13,'[1]Pivot Gioc'!$B:$B,'[1]Pivot Gioc'!$E:$E,"") -> 236 | P13: =IF(_xlfn.XLOOKUP($B13,'[1]Pivot Gioc'!$B:$B,'[1]Pivot Gioc'!$G:$G,"")=0,"",_xlfn.XLOOKUP($B13,'[1]Pivot Gioc'!$B:$B,'[1]Pivot Gioc'!$G:$G)) | Q13: =_xlfn.XLOOKUP(B13,[1]!Tabella4[nome],[1]!Tabella4[PRES]) -> #REF! | R13: =_xlfn.XLOOKUP(B13,[1]!Tabella4[nome],[1]!Tabella4[LEGA TIT]) -> #REF! | S13: =IF(_xlfn.XLOOKUP($B13,'[1]Pivot Gioc'!$B:$B,'[1]Pivot Gioc'!$S:$S)="0,00","",_xlfn.XLOOKUP($B13,'[1]Pivot Gioc'!$B:$B,'[1]Pivot Gioc'!$S:$S)) -> 7.6 | T13: =IF(_xlfn.XLOOKUP($B13,'[1]Pivot Gioc'!$B:$B,'[1]Pivot Gioc'!$T:$T)=0,"",_xlfn.XLOOKUP($B13,'[1]Pivot Gioc'!$B:$B,'[1]Pivot Gioc'!$T:$T)) -> 38 | AB13: Bonazzoli | AC13: 9 | AD13: APPAREGGIATO
B14: Pellegrino M. | C14: =_xlfn.IFNA(_xlfn.XLOOKUP(B14,'[1]ROSE SQUADRE'!$N:$N,'[1]ROSE SQUADRE'!$O:$O),"") -> APPAREGGIATO | D14: =_xlfn.XLOOKUP($B14,'[1]Pivot Gioc'!$B:$B,'[1]Pivot Gioc'!$Q:$Q,"") -> 9 | E14: =_xlfn.XLOOKUP($B14,'[1]Pivot Gioc'!$B:$B,'[1]Pivot Gioc'!$N:$N,"") -> 0 | F14: =_xlfn.XLOOKUP($B14,'[1]Pivot Gioc'!$B:$B,'[1]Pivot Gioc'!$J:$J,"") -> 1 | G14: =_xlfn.XLOOKUP($B14,'[1]Pivot Gioc'!$B:$B,'[1]Pivot Gioc'!$I:$I,"") -> 0 | H14: =_xlfn.XLOOKUP($B14,'[1]Pivot Gioc'!$B:$B,'[1]Pivot Gioc'!$H:$H,"") -> 0 | I14: =_xlfn.XLOOKUP($B14,'[1]Pivot Gioc'!$B:$B,'[1]Pivot Gioc'!$P:$P,"") -> 0 | J14: =_xlfn.XLOOKUP($B14,'[1]Pivot Gioc'!$B:$B,'[1]Pivot Gioc'!$L:$L,"") -> 5 | K14: =_xlfn.XLOOKUP($B14,'[1]Pivot Gioc'!$B:$B,'[1]Pivot Gioc'!$M:$M,"") -> 0 | L14: =_xlfn.XLOOKUP($B14,'[1]Pivot Gioc'!$B:$B,'[1]Pivot Gioc'!$K:$K,"") -> 0 | M14: =_xlfn.XLOOKUP($B14,'[1]Pivot Gioc'!$B:$B,'[1]Pivot Gioc'!$C:$C,"") -> 5.9857143 | N14: =_xlfn.XLOOKUP($B14,'[1]Pivot Gioc'!$B:$B,'[1]Pivot Gioc'!$D:$D,"") -> 6.8 | O14: =_xlfn.XLOOKUP($B14,'[1]Pivot Gioc'!$B:$B,'[1]Pivot Gioc'!$E:$E,"") -> 238 | P14: =IF(_xlfn.XLOOKUP($B14,'[1]Pivot Gioc'!$B:$B,'[1]Pivot Gioc'!$G:$G,"")=0,"",_xlfn.XLOOKUP($B14,'[1]Pivot Gioc'!$B:$B,'[1]Pivot Gioc'!$G:$G)) | Q14: =_xlfn.XLOOKUP(B14,[1]!Tabella4[nome],[1]!Tabella4[PRES]) -> #REF! | R14: =_xlfn.XLOOKUP(B14,[1]!Tabella4[nome],[1]!Tabella4[LEGA TIT]) -> #REF! | S14: =IF(_xlfn.XLOOKUP($B14,'[1]Pivot Gioc'!$B:$B,'[1]Pivot Gioc'!$S:$S)="0,00","",_xlfn.XLOOKUP($B14,'[1]Pivot Gioc'!$B:$B,'[1]Pivot Gioc'!$S:$S)) -> 6.8214286 | T14: =IF(_xlfn.XLOOKUP($B14,'[1]Pivot Gioc'!$B:$B,'[1]Pivot Gioc'!$T:$T)=0,"",_xlfn.XLOOKUP($B14,'[1]Pivot Gioc'!$B:$B,'[1]Pivot Gioc'!$T:$T)) -> 95.5 | AB14: Pellegrino M. | AC14: 9 | AD14: APPAREGGIATO
B15: Davis K. | C15: =_xlfn.IFNA(_xlfn.XLOOKUP(B15,'[1]ROSE SQUADRE'!$N:$N,'[1]ROSE SQUADRE'!$O:$O),"") -> PARTIZAN DEGRADO | D15: =_xlfn.XLOOKUP($B15,'[1]Pivot Gioc'!$B:$B,'[1]Pivot Gioc'!$Q:$Q,"") -> 9 | E15: =_xlfn.XLOOKUP($B15,'[1]Pivot Gioc'!$B:$B,'[1]Pivot Gioc'!$N:$N,"") -> 3 | F15: =_xlfn.XLOOKUP($B15,'[1]Pivot Gioc'!$B:$B,'[1]Pivot Gioc'!$J:$J,"") -> 3 | G15: =_xlfn.XLOOKUP($B15,'[1]Pivot Gioc'!$B:$B,'[1]Pivot Gioc'!$I:$I,"") -> 0 | H15: =_xlfn.XLOOKUP($B15,'[1]Pivot Gioc'!$B:$B,'[1]Pivot Gioc'!$H:$H,"") -> 0 | I15: =_xlfn.XLOOKUP($B15,'[1]Pivot Gioc'!$B:$B,'[1]Pivot Gioc'!$P:$P,"") -> 0 | J15: =_xlfn.XLOOKUP($B15,'[1]Pivot Gioc'!$B:$B,'[1]Pivot Gioc'!$L:$L,"") -> 4 | K15: =_xlfn.XLOOKUP($B15,'[1]Pivot Gioc'!$B:$B,'[1]Pivot Gioc'!$M:$M,"") -> 0 | L15: =_xlfn.XLOOKUP($B15,'[1]Pivot Gioc'!$B:$B,'[1]Pivot Gioc'!$K:$K,"") -> 0 | M15: =_xlfn.XLOOKUP($B15,'[1]Pivot Gioc'!$B:$B,'[1]Pivot Gioc'!$C:$C,"") -> 6.2857143 | N15: =_xlfn.XLOOKUP($B15,'[1]Pivot Gioc'!$B:$B,'[1]Pivot Gioc'!$D:$D,"") -> 7.2857143 | O15: =_xlfn.XLOOKUP($B15,'[1]Pivot Gioc'!$B:$B,'[1]Pivot Gioc'!$E:$E,"") -> 204 | P15: =IF(_xlfn.XLOOKUP($B15,'[1]Pivot Gioc'!$B:$B,'[1]Pivot Gioc'!$G:$G,"")=0,"",_xlfn.XLOOKUP($B15,'[1]Pivot Gioc'!$B:$B,'[1]Pivot Gioc'!$G:$G)) | Q15: =_xlfn.XLOOKUP(B15,[1]!Tabella4[nome],[1]!Tabella4[PRES]) -> #REF! | R15: =_xlfn.XLOOKUP(B15,[1]!Tabella4[nome],[1]!Tabella4[LEGA TIT]) -> #REF! | S15: =IF(_xlfn.XLOOKUP($B15,'[1]Pivot Gioc'!$B:$B,'[1]Pivot Gioc'!$S:$S)="0,00","",_xlfn.XLOOKUP($B15,'[1]Pivot Gioc'!$B:$B,'[1]Pivot Gioc'!$S:$S)) -> 7.3125 | T15: =IF(_xlfn.XLOOKUP($B15,'[1]Pivot Gioc'!$B:$B,'[1]Pivot Gioc'!$T:$T)=0,"",_xlfn.XLOOKUP($B15,'[1]Pivot Gioc'!$B:$B,'[1]Pivot Gioc'!$T:$T)) -> 117 | W15: media fanta voto | AB15: Davis K. | AC15: 9 | AD15: PARTIZAN DEGRADO | AG15: espulsioni | AL15: GOL SUBITI | AQ15: RIGORI SBAGLIATI
B16: Orsolini | C16: =_xlfn.IFNA(_xlfn.XLOOKUP(B16,'[1]ROSE SQUADRE'!$N:$N,'[1]ROSE SQUADRE'!$O:$O),"") -> PARTIZAN DEGRADO | D16: =_xlfn.XLOOKUP($B16,'[1]Pivot Gioc'!$B:$B,'[1]Pivot Gioc'!$Q:$Q,"") -> 9 | E16: =_xlfn.XLOOKUP($B16,'[1]Pivot Gioc'!$B:$B,'[1]Pivot Gioc'!$N:$N,"") -> 1 | F16: =_xlfn.XLOOKUP($B16,'[1]Pivot Gioc'!$B:$B,'[1]Pivot Gioc'!$J:$J,"") -> 4 | G16: =_xlfn.XLOOKUP($B16,'[1]Pivot Gioc'!$B:$B,'[1]Pivot Gioc'!$I:$I,"") -> 2 | H16: =_xlfn.XLOOKUP($B16,'[1]Pivot Gioc'!$B:$B,'[1]Pivot Gioc'!$H:$H,"") -> 0 | I16: =_xlfn.XLOOKUP($B16,'[1]Pivot Gioc'!$B:$B,'[1]Pivot Gioc'!$P:$P,"") -> 0 | J16: =_xlfn.XLOOKUP($B16,'[1]Pivot Gioc'!$B:$B,'[1]Pivot Gioc'!$L:$L,"") -> 2 | K16: =_xlfn.XLOOKUP($B16,'[1]Pivot Gioc'!$B:$B,'[1]Pivot Gioc'!$M:$M,"") -> 0 | L16: =_xlfn.XLOOKUP($B16,'[1]Pivot Gioc'!$B:$B,'[1]Pivot Gioc'!$K:$K,"") -> 0 | M16: =_xlfn.XLOOKUP($B16,'[1]Pivot Gioc'!$B:$B,'[1]Pivot Gioc'!$C:$C,"") -> 6.03125 | N16: =_xlfn.XLOOKUP($B16,'[1]Pivot Gioc'!$B:$B,'[1]Pivot Gioc'!$D:$D,"") -> 6.75 | O16: =_xlfn.XLOOKUP($B16,'[1]Pivot Gioc'!$B:$B,'[1]Pivot Gioc'!$E:$E,"") -> 216 | P16: =IF(_xlfn.XLOOKUP($B16,'[1]Pivot Gioc'!$B:$B,'[1]Pivot Gioc'!$G:$G,"")=0,"",_xlfn.XLOOKUP($B16,'[1]Pivot Gioc'!$B:$B,'[1]Pivot Gioc'!$G:$G)) | Q16: =_xlfn.XLOOKUP(B16,[1]!Tabella4[nome],[1]!Tabella4[PRES]) -> #REF! | R16: =_xlfn.XLOOKUP(B16,[1]!Tabella4[nome],[1]!Tabella4[LEGA TIT]) -> #REF! | S16: =IF(_xlfn.XLOOKUP($B16,'[1]Pivot Gioc'!$B:$B,'[1]Pivot Gioc'!$S:$S)="0,00","",_xlfn.XLOOKUP($B16,'[1]Pivot Gioc'!$B:$B,'[1]Pivot Gioc'!$S:$S)) -> 6.75 | T16: =IF(_xlfn.XLOOKUP($B16,'[1]Pivot Gioc'!$B:$B,'[1]Pivot Gioc'!$T:$T)=0,"",_xlfn.XLOOKUP($B16,'[1]Pivot Gioc'!$B:$B,'[1]Pivot Gioc'!$T:$T)) -> 216 | W16: {=INDEX(_xlfn._xlws.SORT($B$3:$N$508,13,-1),_xlfn.SEQUENCE(10),1)} -> Lukaku | X16: {=INDEX(_xlfn._xlws.SORT($B$3:$N$508,13,-1),_xlfn.SEQUENCE(10),13)} -> 10.5 | Y16: {=INDEX(_xlfn._xlws.SORT($B$3:$N$508,13,-1),_xlfn.SEQUENCE(10),2)} -> SAN GRIA | AB16: Orsolini | AC16: 9 | AD16: PARTIZAN DEGRADO | AG16: {=INDEX(_xlfn._xlws.SORT($B$3:$N$508,10,-1),_xlfn.SEQUENCE(10),1)} -> Wesley | AH16: {=INDEX(_xlfn._xlws.SORT($B$3:$N$508,10,-1),_xlfn.SEQUENCE(10),10)} -> 2 | AI16: {=INDEX(_xlfn._xlws.SORT($B$3:$N$508,10,-1),_xlfn.SEQUENCE(10),2)} -> APPAREGGIATO | AL16: {=INDEX(_xlfn._xlws.SORT(_xlfn._xlws.FILTER($B$3:$P$508,($A$3:$A$508="p")*($P$3:$P$508<>"")),14,-1),_xlfn.SEQUENCE(10),1)} -> #N/A | AM16: {=INDEX(_xlfn._xlws.SORT(_xlfn._xlws.FILTER($B$3:$P$508,($A$3:$A$508="p")*($P$3:$P$508<>"")),14,-1),_xlfn.SEQUENCE(10),14)} -> #N/A | AN16: {=INDEX(_xlfn._xlws.SORT(_xlfn._xlws.FILTER($B$3:$P$508,($A$3:$A$508="p")*($P$3:$P$508<>"")),14,-1),_xlfn.SEQUENCE(10),2)} -> #N/A | AQ16: {=INDEX(_xlfn._xlws.SORT($B$3:$N$508,6,-1),_xlfn.SEQUENCE(10),1)} -> Paz N. | AR16: {=INDEX(_xlfn._xlws.SORT($B$3:$N$508,6,-1),_xlfn.SEQUENCE(10),6)} -> 2 | AS16: {=INDEX(_xlfn._xlws.SORT($B$3:$N$508,6,-1),_xlfn.SEQUENCE(10),2)} -> AC ASPARAGHESE
A17: P | B17: Calhanoglu | C17: =_xlfn.IFNA(_xlfn.XLOOKUP(B17,'[1]ROSE SQUADRE'!$N:$N,'[1]ROSE SQUADRE'!$O:$O),"") -> SAN GRIA | D17: =_xlfn.XLOOKUP($B17,'[1]Pivot Gioc'!$B:$B,'[1]Pivot Gioc'!$Q:$Q,"") -> 9 | E17: =_xlfn.XLOOKUP($B17,'[1]Pivot Gioc'!$B:$B,'[1]Pivot Gioc'!$N:$N,"") -> 4 | F17: =_xlfn.XLOOKUP($B17,'[1]Pivot Gioc'!$B:$B,'[1]Pivot Gioc'!$J:$J,"") -> 4 | G17: =_xlfn.XLOOKUP($B17,'[1]Pivot Gioc'!$B:$B,'[1]Pivot Gioc'!$I:$I,"") -> 1 | H17: =_xlfn.XLOOKUP($B17,'[1]Pivot Gioc'!$B:$B,'[1]Pivot Gioc'!$H:$H,"") -> 0 | I17: =_xlfn.XLOOKUP($B17,'[1]Pivot Gioc'!$B:$B,'[1]Pivot Gioc'!$P:$P,"") -> 0 | J17: =_xlfn.XLOOKUP($B17,'[1]Pivot Gioc'!$B:$B,'[1]Pivot Gioc'!$L:$L,"") -> 7 | K17: =_xlfn.XLOOKUP($B17,'[1]Pivot Gioc'!$B:$B,'[1]Pivot Gioc'!$M:$M,"") -> 0 | L17: =_xlfn.XLOOKUP($B17,'[1]Pivot Gioc'!$B:$B,'[1]Pivot Gioc'!$K:$K,"") -> 0 | M17: =_xlfn.XLOOKUP($B17,'[1]Pivot Gioc'!$B:$B,'[1]Pivot Gioc'!$C:$C,"") -> 6.5952381 | N17: =_xlfn.XLOOKUP($B17,'[1]Pivot Gioc'!$B:$B,'[1]Pivot Gioc'!$D:$D,"") -> 7.8095238 | O17: =_xlfn.XLOOKUP($B17,'[1]Pivot Gioc'!$B:$B,'[1]Pivot Gioc'!$E:$E,"") -> 164 | P17: =IF(_xlfn.XLOOKUP($B17,'[1]Pivot Gioc'!$B:$B,'[1]Pivot Gioc'!$G:$G,"")=0,"",_xlfn.XLOOKUP($B17,'[1]Pivot Gioc'!$B:$B,'[1]Pivot Gioc'!$G:$G)) | Q17: =_xlfn.XLOOKUP(B17,[1]!Tabella4[nome],[1]!Tabella4[PRES]) -> #REF! | R17: =_xlfn.XLOOKUP(B17,[1]!Tabella4[nome],[1]!Tabella4[LEGA TIT]) -> #REF! | S17: =IF(_xlfn.XLOOKUP($B17,'[1]Pivot Gioc'!$B:$B,'[1]Pivot Gioc'!$S:$S)="0,00","",_xlfn.XLOOKUP($B17,'[1]Pivot Gioc'!$B:$B,'[1]Pivot Gioc'!$S:$S)) -> 7.8095238 | T17: =IF(_xlfn.XLOOKUP($B17,'[1]Pivot Gioc'!$B:$B,'[1]Pivot Gioc'!$T:$T)=0,"",_xlfn.XLOOKUP($B17,'[1]Pivot Gioc'!$B:$B,'[1]Pivot Gioc'!$T:$T)) -> 164 | W17: Malen | X17: 9.3055556 | Y17: APPAREGGIATO | AB17: Calhanoglu | AC17: 9 | AD17: SAN GRIA | AG17: Troilo | AH17: 2 | AL17: #N/A | AM17: #N/A | AN17: #N/A | AQ17: Orsolini | AR17: 2 | AS17: PARTIZAN DEGRADO
A18: D | B18: Leao | C18: =_xlfn.IFNA(_xlfn.XLOOKUP(B18,'[1]ROSE SQUADRE'!$N:$N,'[1]ROSE SQUADRE'!$O:$O),"") -> SAN GRIA | D18: =_xlfn.XLOOKUP($B18,'[1]Pivot Gioc'!$B:$B,'[1]Pivot Gioc'!$Q:$Q,"") -> 9 | E18: =_xlfn.XLOOKUP($B18,'[1]Pivot Gioc'!$B:$B,'[1]Pivot Gioc'!$N:$N,"") -> 3 | F18: =_xlfn.XLOOKUP($B18,'[1]Pivot Gioc'!$B:$B,'[1]Pivot Gioc'!$J:$J,"") -> 2 | G18: =_xlfn.XLOOKUP($B18,'[1]Pivot Gioc'!$B:$B,'[1]Pivot Gioc'!$I:$I,"") -> 0 | H18: =_xlfn.XLOOKUP($B18,'[1]Pivot Gioc'!$B:$B,'[1]Pivot Gioc'!$H:$H,"") -> 0 | I18: =_xlfn.XLOOKUP($B18,'[1]Pivot Gioc'!$B:$B,'[1]Pivot Gioc'!$P:$P,"") -> 0 | J18: =_xlfn.XLOOKUP($B18,'[1]Pivot Gioc'!$B:$B,'[1]Pivot Gioc'!$L:$L,"") -> 5 | K18: =_xlfn.XLOOKUP($B18,'[1]Pivot Gioc'!$B:$B,'[1]Pivot Gioc'!$M:$M,"") -> 0 | L18: =_xlfn.XLOOKUP($B18,'[1]Pivot Gioc'!$B:$B,'[1]Pivot Gioc'!$K:$K,"") -> 0 | M18: =_xlfn.XLOOKUP($B18,'[1]Pivot Gioc'!$B:$B,'[1]Pivot Gioc'!$C:$C,"") -> 5.875 | N18: =_xlfn.XLOOKUP($B18,'[1]Pivot Gioc'!$B:$B,'[1]Pivot Gioc'!$D:$D,"") -> 6.9642857 | O18: =_xlfn.XLOOKUP($B18,'[1]Pivot Gioc'!$B:$B,'[1]Pivot Gioc'!$E:$E,"") -> 195 | P18: =IF(_xlfn.XLOOKUP($B18,'[1]Pivot Gioc'!$B:$B,'[1]Pivot Gioc'!$G:$G,"")=0,"",_xlfn.XLOOKUP($B18,'[1]Pivot Gioc'!$B:$B,'[1]Pivot Gioc'!$G:$G)) | Q18: =_xlfn.XLOOKUP(B18,[1]!Tabella4[nome],[1]!Tabella4[PRES]) -> #REF! | R18: =_xlfn.XLOOKUP(B18,[1]!Tabella4[nome],[1]!Tabella4[LEGA TIT]) -> #REF! | S18: =IF(_xlfn.XLOOKUP($B18,'[1]Pivot Gioc'!$B:$B,'[1]Pivot Gioc'!$S:$S)="0,00","",_xlfn.XLOOKUP($B18,'[1]Pivot Gioc'!$B:$B,'[1]Pivot Gioc'!$S:$S)) -> 7 | T18: =IF(_xlfn.XLOOKUP($B18,'[1]Pivot Gioc'!$B:$B,'[1]Pivot Gioc'!$T:$T)=0,"",_xlfn.XLOOKUP($B18,'[1]Pivot Gioc'!$B:$B,'[1]Pivot Gioc'!$T:$T)) -> 189 | W18: Martinez L. | X18: 8.6428571 | Y18: HERTHA VERNELLO | AB18: Leao | AC18: 9 | AD18: SAN GRIA | AG18: Pinamonti | AH18: 1 | AI18: AC ASPARAGHESE | AL18: #N/A | AM18: #N/A | AN18: #N/A | AQ18: Malen | AR18: 1 | AS18: APPAREGGIATO
A19: C | B19: McTominay | C19: =_xlfn.IFNA(_xlfn.XLOOKUP(B19,'[1]ROSE SQUADRE'!$N:$N,'[1]ROSE SQUADRE'!$O:$O),"") -> SAN GRIA | D19: =_xlfn.XLOOKUP($B19,'[1]Pivot Gioc'!$B:$B,'[1]Pivot Gioc'!$Q:$Q,"") -> 9 | E19: =_xlfn.XLOOKUP($B19,'[1]Pivot Gioc'!$B:$B,'[1]Pivot Gioc'!$N:$N,"") -> 2 | F19: =_xlfn.XLOOKUP($B19,'[1]Pivot Gioc'!$B:$B,'[1]Pivot Gioc'!$J:$J,"") -> 0 | G19: =_xlfn.XLOOKUP($B19,'[1]Pivot Gioc'!$B:$B,'[1]Pivot Gioc'!$I:$I,"") -> 1 | H19: =_xlfn.XLOOKUP($B19,'[1]Pivot Gioc'!$B:$B,'[1]Pivot Gioc'!$H:$H,"") -> 0 | I19: =_xlfn.XLOOKUP($B19,'[1]Pivot Gioc'!$B:$B,'[1]Pivot Gioc'!$P:$P,"") -> 0 | J19: =_xlfn.XLOOKUP($B19,'[1]Pivot Gioc'!$B:$B,'[1]Pivot Gioc'!$L:$L,"") -> 1 | K19: =_xlfn.XLOOKUP($B19,'[1]Pivot Gioc'!$B:$B,'[1]Pivot Gioc'!$M:$M,"") -> 0 | L19: =_xlfn.XLOOKUP($B19,'[1]Pivot Gioc'!$B:$B,'[1]Pivot Gioc'!$K:$K,"") -> 0 | M19: =_xlfn.XLOOKUP($B19,'[1]Pivot Gioc'!$B:$B,'[1]Pivot Gioc'!$C:$C,"") -> 6.3709677 | N19: =_xlfn.XLOOKUP($B19,'[1]Pivot Gioc'!$B:$B,'[1]Pivot Gioc'!$D:$D,"") -> 7.3225806 | O19: =_xlfn.XLOOKUP($B19,'[1]Pivot Gioc'!$B:$B,'[1]Pivot Gioc'!$E:$E,"") -> 227 | P19: =IF(_xlfn.XLOOKUP($B19,'[1]Pivot Gioc'!$B:$B,'[1]Pivot Gioc'!$G:$G,"")=0,"",_xlfn.XLOOKUP($B19,'[1]Pivot Gioc'!$B:$B,'[1]Pivot Gioc'!$G:$G)) | Q19: =_xlfn.XLOOKUP(B19,[1]!Tabella4[nome],[1]!Tabella4[PRES]) -> #REF! | R19: =_xlfn.XLOOKUP(B19,[1]!Tabella4[nome],[1]!Tabella4[LEGA TIT]) -> #REF! | S19: =IF(_xlfn.XLOOKUP($B19,'[1]Pivot Gioc'!$B:$B,'[1]Pivot Gioc'!$S:$S)="0,00","",_xlfn.XLOOKUP($B19,'[1]Pivot Gioc'!$B:$B,'[1]Pivot Gioc'!$S:$S)) -> 7.3833333 | T19: =IF(_xlfn.XLOOKUP($B19,'[1]Pivot Gioc'!$B:$B,'[1]Pivot Gioc'!$T:$T)=0,"",_xlfn.XLOOKUP($B19,'[1]Pivot Gioc'!$B:$B,'[1]Pivot Gioc'!$T:$T)) -> 221.5 | W19: Belotti | X19: 7.875 | AB19: McTominay | AC19: 9 | AD19: SAN GRIA | AG19: Berardi | AH19: 1 | AI19: HERTHA VERNELLO | AL19: #N/A | AM19: #N/A | AN19: #N/A | AQ19: Yildiz | AR19: 1 | AS19: SESTO ASENSIO
B20: Pinamonti | C20: =_xlfn.IFNA(_xlfn.XLOOKUP(B20,'[1]ROSE SQUADRE'!$N:$N,'[1]ROSE SQUADRE'!$O:$O),"") -> AC ASPARAGHESE | D20: =_xlfn.XLOOKUP($B20,'[1]Pivot Gioc'!$B:$B,'[1]Pivot Gioc'!$Q:$Q,"") -> 8 | E20: =_xlfn.XLOOKUP($B20,'[1]Pivot Gioc'!$B:$B,'[1]Pivot Gioc'!$N:$N,"") -> 3 | F20: =_xlfn.XLOOKUP($B20,'[1]Pivot Gioc'!$B:$B,'[1]Pivot Gioc'!$J:$J,"") -> 0 | G20: =_xlfn.XLOOKUP($B20,'[1]Pivot Gioc'!$B:$B,'[1]Pivot Gioc'!$I:$I,"") -> 1 | H20: =_xlfn.XLOOKUP($B20,'[1]Pivot Gioc'!$B:$B,'[1]Pivot Gioc'!$H:$H,"") -> 0 | I20: =_xlfn.XLOOKUP($B20,'[1]Pivot Gioc'!$B:$B,'[1]Pivot Gioc'!$P:$P,"") -> 0 | J20: =_xlfn.XLOOKUP($B20,'[1]Pivot Gioc'!$B:$B,'[1]Pivot Gioc'!$L:$L,"") -> 2 | K20: =_xlfn.XLOOKUP($B20,'[1]Pivot Gioc'!$B:$B,'[1]Pivot Gioc'!$M:$M,"") -> 1 | L20: =_xlfn.XLOOKUP($B20,'[1]Pivot Gioc'!$B:$B,'[1]Pivot Gioc'!$K:$K,"") -> 0 | M20: =_xlfn.XLOOKUP($B20,'[1]Pivot Gioc'!$B:$B,'[1]Pivot Gioc'!$C:$C,"") -> 5.875 | N20: =_xlfn.XLOOKUP($B20,'[1]Pivot Gioc'!$B:$B,'[1]Pivot Gioc'!$D:$D,"") -> 6.6875 | O20: =_xlfn.XLOOKUP($B20,'[1]Pivot Gioc'!$B:$B,'[1]Pivot Gioc'!$E:$E,"") -> 214 | P20: =IF(_xlfn.XLOOKUP($B20,'[1]Pivot Gioc'!$B:$B,'[1]Pivot Gioc'!$G:$G,"")=0,"",_xlfn.XLOOKUP($B20,'[1]Pivot Gioc'!$B:$B,'[1]Pivot Gioc'!$G:$G)) | Q20: =_xlfn.XLOOKUP(B20,[1]!Tabella4[nome],[1]!Tabella4[PRES]) -> #REF! | R20: =_xlfn.XLOOKUP(B20,[1]!Tabella4[nome],[1]!Tabella4[LEGA TIT]) -> #REF! | S20: =IF(_xlfn.XLOOKUP($B20,'[1]Pivot Gioc'!$B:$B,'[1]Pivot Gioc'!$S:$S)="0,00","",_xlfn.XLOOKUP($B20,'[1]Pivot Gioc'!$B:$B,'[1]Pivot Gioc'!$S:$S)) -> 6.9137931 | T20: =IF(_xlfn.XLOOKUP($B20,'[1]Pivot Gioc'!$B:$B,'[1]Pivot Gioc'!$T:$T)=0,"",_xlfn.XLOOKUP($B20,'[1]Pivot Gioc'!$B:$B,'[1]Pivot Gioc'!$T:$T)) -> 200.5 | W20: Thuram | X20: 7.8333333 | Y20: PESCICULINI FC | AB20: Pinamonti | AC20: 8 | AD20: AC ASPARAGHESE | AG20: Orban G. | AH20: 1 | AI20: SESTO ASENSIO | AL20: #N/A | AM20: #N/A | AN20: #N/A | AQ20: Calhanoglu | AR20: 1 | AS20: SAN GRIA
A21: C | B21: Kean | C21: =_xlfn.IFNA(_xlfn.XLOOKUP(B21,'[1]ROSE SQUADRE'!$N:$N,'[1]ROSE SQUADRE'!$O:$O),"") -> HERTHA VERNELLO | D21: =_xlfn.XLOOKUP($B21,'[1]Pivot Gioc'!$B:$B,'[1]Pivot Gioc'!$Q:$Q,"") -> 8 | E21: =_xlfn.XLOOKUP($B21,'[1]Pivot Gioc'!$B:$B,'[1]Pivot Gioc'!$N:$N,"") -> 1 | F21: =_xlfn.XLOOKUP($B21,'[1]Pivot Gioc'!$B:$B,'[1]Pivot Gioc'!$J:$J,"") -> 2 | G21: =_xlfn.XLOOKUP($B21,'[1]Pivot Gioc'!$B:$B,'[1]Pivot Gioc'!$I:$I,"") -> 0 | H21: =_xlfn.XLOOKUP($B21,'[1]Pivot Gioc'!$B:$B,'[1]Pivot Gioc'!$H:$H,"") -> 0 | I21: =_xlfn.XLOOKUP($B21,'[1]Pivot Gioc'!$B:$B,'[1]Pivot Gioc'!$P:$P,"") -> 0 | J21: =_xlfn.XLOOKUP($B21,'[1]Pivot Gioc'!$B:$B,'[1]Pivot Gioc'!$L:$L,"") -> 4 | K21: =_xlfn.XLOOKUP($B21,'[1]Pivot Gioc'!$B:$B,'[1]Pivot Gioc'!$M:$M,"") -> 0 | L21: =_xlfn.XLOOKUP($B21,'[1]Pivot Gioc'!$B:$B,'[1]Pivot Gioc'!$K:$K,"") -> 0 | M21: =_xlfn.XLOOKUP($B21,'[1]Pivot Gioc'!$B:$B,'[1]Pivot Gioc'!$C:$C,"") -> 5.9583333 | N21: =_xlfn.XLOOKUP($B21,'[1]Pivot Gioc'!$B:$B,'[1]Pivot Gioc'!$D:$D,"") -> 7.0416667 | O21: =_xlfn.XLOOKUP($B21,'[1]Pivot Gioc'!$B:$B,'[1]Pivot Gioc'!$E:$E,"") -> 169 | P21: =IF(_xlfn.XLOOKUP($B21,'[1]Pivot Gioc'!$B:$B,'[1]Pivot Gioc'!$G:$G,"")=0,"",_xlfn.XLOOKUP($B21,'[1]Pivot Gioc'!$B:$B,'[1]Pivot Gioc'!$G:$G)) | Q21: =_xlfn.XLOOKUP(B21,[1]!Tabella4[nome],[1]!Tabella4[PRES]) -> #REF! | R21: =_xlfn.XLOOKUP(B21,[1]!Tabella4[nome],[1]!Tabella4[LEGA TIT]) -> #REF! | S21: =IF(_xlfn.XLOOKUP($B21,'[1]Pivot Gioc'!$B:$B,'[1]Pivot Gioc'!$S:$S)="0,00","",_xlfn.XLOOKUP($B21,'[1]Pivot Gioc'!$B:$B,'[1]Pivot Gioc'!$S:$S)) -> 6.8695652 | T21: =IF(_xlfn.XLOOKUP($B21,'[1]Pivot Gioc'!$B:$B,'[1]Pivot Gioc'!$T:$T)=0,"",_xlfn.XLOOKUP($B21,'[1]Pivot Gioc'!$B:$B,'[1]Pivot Gioc'!$T:$T)) -> 158 | W21: Calhanoglu | X21: 7.8095238 | Y21: SAN GRIA | AB21: Kean | AC21: 8 | AD21: HERTHA VERNELLO | AG21: Rabiot | AH21: 1 | AI21: PARTIZAN DEGRADO | AL21: #N/A | AM21: #N/A | AN21: #N/A | AQ21: McTominay | AR21: 1 | AS21: SAN GRIA
B22: Vlasic | C22: =_xlfn.IFNA(_xlfn.XLOOKUP(B22,'[1]ROSE SQUADRE'!$N:$N,'[1]ROSE SQUADRE'!$O:$O),"") -> PESCICULINI FC | D22: =_xlfn.XLOOKUP($B22,'[1]Pivot Gioc'!$B:$B,'[1]Pivot Gioc'!$Q:$Q,"") -> 8 | E22: =_xlfn.XLOOKUP($B22,'[1]Pivot Gioc'!$B:$B,'[1]Pivot Gioc'!$N:$N,"") -> 3 | F22: =_xlfn.XLOOKUP($B22,'[1]Pivot Gioc'!$B:$B,'[1]Pivot Gioc'!$J:$J,"") -> 5 | G22: =_xlfn.XLOOKUP($B22,'[1]Pivot Gioc'!$B:$B,'[1]Pivot Gioc'!$I:$I,"") -> 0 | H22: =_xlfn.XLOOKUP($B22,'[1]Pivot Gioc'!$B:$B,'[1]Pivot Gioc'!$H:$H,"") -> 0 | I22: =_xlfn.XLOOKUP($B22,'[1]Pivot Gioc'!$B:$B,'[1]Pivot Gioc'!$P:$P,"") -> 0 | J22: =_xlfn.XLOOKUP($B22,'[1]Pivot Gioc'!$B:$B,'[1]Pivot Gioc'!$L:$L,"") -> 6 | K22: =_xlfn.XLOOKUP($B22,'[1]Pivot Gioc'!$B:$B,'[1]Pivot Gioc'!$M:$M,"") -> 0 | L22: =_xlfn.XLOOKUP($B22,'[1]Pivot Gioc'!$B:$B,'[1]Pivot Gioc'!$K:$K,"") -> 0 | M22: =_xlfn.XLOOKUP($B22,'[1]Pivot Gioc'!$B:$B,'[1]Pivot Gioc'!$C:$C,"") -> 6.0428571 | N22: =_xlfn.XLOOKUP($B22,'[1]Pivot Gioc'!$B:$B,'[1]Pivot Gioc'!$D:$D,"") -> 6.7857143 | O22: =_xlfn.XLOOKUP($B22,'[1]Pivot Gioc'!$B:$B,'[1]Pivot Gioc'!$E:$E,"") -> 237.5 | P22: =IF(_xlfn.XLOOKUP($B22,'[1]Pivot Gioc'!$B:$B,'[1]Pivot Gioc'!$G:$G,"")=0,"",_xlfn.XLOOKUP($B22,'[1]Pivot Gioc'!$B:$B,'[1]Pivot Gioc'!$G:$G)) | Q22: =_xlfn.XLOOKUP(B22,[1]!Tabella4[nome],[1]!Tabella4[PRES]) -> #REF! | R22: =_xlfn.XLOOKUP(B22,[1]!Tabella4[nome],[1]!Tabella4[LEGA TIT]) -> #REF! | S22: =IF(_xlfn.XLOOKUP($B22,'[1]Pivot Gioc'!$B:$B,'[1]Pivot Gioc'!$S:$S)="0,00","",_xlfn.XLOOKUP($B22,'[1]Pivot Gioc'!$B:$B,'[1]Pivot Gioc'!$S:$S)) -> 6.578125 | T22: =IF(_xlfn.XLOOKUP($B22,'[1]Pivot Gioc'!$B:$B,'[1]Pivot Gioc'!$T:$T)=0,"",_xlfn.XLOOKUP($B22,'[1]Pivot Gioc'!$B:$B,'[1]Pivot Gioc'!$T:$T)) -> 210.5 | W22: Dimarco | X22: 7.7878788 | Y22: ATL IMPROVVISATO | AB22: Vlasic | AC22: 8 | AD22: PESCICULINI FC | AG22: Banda | AH22: 1 | AL22: #N/A | AM22: #N/A | AN22: #N/A | AQ22: Pinamonti | AR22: 1 | AS22: AC ASPARAGHESE
A23: C | B23: Moreo | C23: =_xlfn.IFNA(_xlfn.XLOOKUP(B23,'[1]ROSE SQUADRE'!$N:$N,'[1]ROSE SQUADRE'!$O:$O),"") -> AC ASPARAGHESE | D23: =_xlfn.XLOOKUP($B23,'[1]Pivot Gioc'!$B:$B,'[1]Pivot Gioc'!$Q:$Q,"") -> 7 | E23: =_xlfn.XLOOKUP($B23,'[1]Pivot Gioc'!$B:$B,'[1]Pivot Gioc'!$N:$N,"") -> 0 | F23: =_xlfn.XLOOKUP($B23,'[1]Pivot Gioc'!$B:$B,'[1]Pivot Gioc'!$J:$J,"") -> 2 | G23: =_xlfn.XLOOKUP($B23,'[1]Pivot Gioc'!$B:$B,'[1]Pivot Gioc'!$I:$I,"") -> 0 | H23: =_xlfn.XLOOKUP($B23,'[1]Pivot Gioc'!$B:$B,'[1]Pivot Gioc'!$H:$H,"") -> 0 | I23: =_xlfn.XLOOKUP($B23,'[1]Pivot Gioc'!$B:$B,'[1]Pivot Gioc'!$P:$P,"") -> 0 | J23: =_xlfn.XLOOKUP($B23,'[1]Pivot Gioc'!$B:$B,'[1]Pivot Gioc'!$L:$L,"") -> 2 | K23: =_xlfn.XLOOKUP($B23,'[1]Pivot Gioc'!$B:$B,'[1]Pivot Gioc'!$M:$M,"") -> 0 | L23: =_xlfn.XLOOKUP($B23,'[1]Pivot Gioc'!$B:$B,'[1]Pivot Gioc'!$K:$K,"") -> 0 | M23: =_xlfn.XLOOKUP($B23,'[1]Pivot Gioc'!$B:$B,'[1]Pivot Gioc'!$C:$C,"") -> 5.9848485 | N23: =_xlfn.XLOOKUP($B23,'[1]Pivot Gioc'!$B:$B,'[1]Pivot Gioc'!$D:$D,"") -> 6.5909091 | O23: =_xlfn.XLOOKUP($B23,'[1]Pivot Gioc'!$B:$B,'[1]Pivot Gioc'!$E:$E,"") -> 217.5 | P23: =IF(_xlfn.XLOOKUP($B23,'[1]Pivot Gioc'!$B:$B,'[1]Pivot Gioc'!$G:$G,"")=0,"",_xlfn.XLOOKUP($B23,'[1]Pivot Gioc'!$B:$B,'[1]Pivot Gioc'!$G:$G)) | Q23: =_xlfn.XLOOKUP(B23,[1]!Tabella4[nome],[1]!Tabella4[PRES]) -> #REF! | R23: =_xlfn.XLOOKUP(B23,[1]!Tabella4[nome],[1]!Tabella4[LEGA TIT]) -> #REF! | S23: =IF(_xlfn.XLOOKUP($B23,'[1]Pivot Gioc'!$B:$B,'[1]Pivot Gioc'!$S:$S)="0,00","",_xlfn.XLOOKUP($B23,'[1]Pivot Gioc'!$B:$B,'[1]Pivot Gioc'!$S:$S)) -> 5 | T23: =IF(_xlfn.XLOOKUP($B23,'[1]Pivot Gioc'!$B:$B,'[1]Pivot Gioc'!$T:$T)=0,"",_xlfn.XLOOKUP($B23,'[1]Pivot Gioc'!$B:$B,'[1]Pivot Gioc'!$T:$T)) -> 5 | W23: Hojlund | X23: 7.6212121 | Y23: SAN GRIA | AG23: Gudmundsson A. | AH23: 1 | AI23: APPAREGGIATO | AL23: #N/A | AM23: #N/A | AN23: #N/A | AQ23: Berardi | AR23: 1 | AS23: HERTHA VERNELLO
A24: C | B24: Dimarco | C24: =_xlfn.IFNA(_xlfn.XLOOKUP(B24,'[1]ROSE SQUADRE'!$N:$N,'[1]ROSE SQUADRE'!$O:$O),"") -> ATL IMPROVVISATO | D24: =_xlfn.XLOOKUP($B24,'[1]Pivot Gioc'!$B:$B,'[1]Pivot Gioc'!$Q:$Q,"") -> 7 | E24: =_xlfn.XLOOKUP($B24,'[1]Pivot Gioc'!$B:$B,'[1]Pivot Gioc'!$N:$N,"") -> 17 | F24: =_xlfn.XLOOKUP($B24,'[1]Pivot Gioc'!$B:$B,'[1]Pivot Gioc'!$J:$J,"") -> 0 | G24: =_xlfn.XLOOKUP($B24,'[1]Pivot Gioc'!$B:$B,'[1]Pivot Gioc'!$I:$I,"") -> 0 | H24: =_xlfn.XLOOKUP($B24,'[1]Pivot Gioc'!$B:$B,'[1]Pivot Gioc'!$H:$H,"") -> 0 | I24: =_xlfn.XLOOKUP($B24,'[1]Pivot Gioc'!$B:$B,'[1]Pivot Gioc'!$P:$P,"") -> 0 | J24: =_xlfn.XLOOKUP($B24,'[1]Pivot Gioc'!$B:$B,'[1]Pivot Gioc'!$L:$L,"") -> 3 | K24: =_xlfn.XLOOKUP($B24,'[1]Pivot Gioc'!$B:$B,'[1]Pivot Gioc'!$M:$M,"") -> 0 | L24: =_xlfn.XLOOKUP($B24,'[1]Pivot Gioc'!$B:$B,'[1]Pivot Gioc'!$K:$K,"") -> 0 | M24: =_xlfn.XLOOKUP($B24,'[1]Pivot Gioc'!$B:$B,'[1]Pivot Gioc'!$C:$C,"") -> 6.6212121 | N24: =_xlfn.XLOOKUP($B24,'[1]Pivot Gioc'!$B:$B,'[1]Pivot Gioc'!$D:$D,"") -> 7.7878788 | O24: =_xlfn.XLOOKUP($B24,'[1]Pivot Gioc'!$B:$B,'[1]Pivot Gioc'!$E:$E,"") -> 257 | P24: =IF(_xlfn.XLOOKUP($B24,'[1]Pivot Gioc'!$B:$B,'[1]Pivot Gioc'!$G:$G,"")=0,"",_xlfn.XLOOKUP($B24,'[1]Pivot Gioc'!$B:$B,'[1]Pivot Gioc'!$G:$G)) | Q24: =_xlfn.XLOOKUP(B24,[1]!Tabella4[nome],[1]!Tabella4[PRES]) -> #REF! | R24: =_xlfn.XLOOKUP(B24,[1]!Tabella4[nome],[1]!Tabella4[LEGA TIT]) -> #REF! | S24: =IF(_xlfn.XLOOKUP($B24,'[1]Pivot Gioc'!$B:$B,'[1]Pivot Gioc'!$S:$S)="0,00","",_xlfn.XLOOKUP($B24,'[1]Pivot Gioc'!$B:$B,'[1]Pivot Gioc'!$S:$S)) -> 7.828125 | T24: =IF(_xlfn.XLOOKUP($B24,'[1]Pivot Gioc'!$B:$B,'[1]Pivot Gioc'!$T:$T)=0,"",_xlfn.XLOOKUP($B24,'[1]Pivot Gioc'!$B:$B,'[1]Pivot Gioc'!$T:$T)) -> 250.5 | W24: Scamacca | X24: 7.6 | Y24: AC ASPARAGHESE | AB24: assist | AG24: Noslin | AH24: 1 | AL24: #N/A | AM24: #N/A | AN24: #N/A | AQ24: Colombo | AR24: 1 | AS24: SAN GRIA
