Workbook

Sheet Lista calciatori
A1: Nome | B1: Sq. | C1: Under | D1: R. | E1: R.MANTRA | F1: FVM/1000
A3: Bijlow | B3: Genoa | C3: 28 | D3: P | E3: Por | F3: 9
A4: Bleve | B4: Lecce | C4: 31 | D4: P | E4: Por | F4: 1
A5: Butez | B5: Como | C5: 31 | D5: P | E5: Por | F5: 28
A6: Caprile | B6: Cagliari | C6: 25 | D6: P | E6: Por | F6: 14
A7: Carnesecchi | B7: Atalanta | C7: 26 | D7: P | E7: Por | F7: 26
A8: Christensen O. | B8: Fiorentina | C8: 27 | D8: P | E8: Por | F8: 1
A9: Contini | B9: Napoli | C9: 30 | D9: P | E9: Por | F9: 1
A10: Corvi | B10: Parma | C10: 25 | D10: P | E10: Por | F10: 1
A11: Daffara | B11: Parma | C11: 22 | D11: P | E11: Por | F11: 3
A12: De Gea | B12: Fiorentina | C12: 36 | D12: P | E12: Por | F12: 23
A13: De Marzi | B13: Roma | C13: 19 | D13: P | E13: Por | F13: 1
A14: Desplanches | B14: Frosinone | C14: 23 | D14: P | E14: Por | F14: 4
... A513: Zapata D. | B513: Torino | C513: 35 | D513: A | E513: Pc | F513: 9

Sheet Foglio1
A1: Nome | B1: Sq. | C1: R. | D1: R.MANTRA | E1: FVM/1000 | G1: media voto | I1: 1 | J1: 2 | K1: 3 | L1: 4 | M1: 5 | N1: 6 | O1: 7 | P1: 8 | Q1: 9 | R1: 10 | S1: 11 | T1: 12 | U1: 13 | V1: 14 | W1: 15 | X1: 16 | Y1: 17 | Z1: 18 | AA1: 19 | AB1: 20 | AC1: 21 | AD1: 22 | AE1: 23 | AF1: 24 | AG1: 25 | AH1: 26 | AI1: 27 | AJ1: 28 | AK1: 29 | AL1: 30 | AM1: 31 | AN1: 32 | AO1: 33 | AP1: 34 | AQ1: 35 | AR1: 36 | AS1: 37 | AT1: 38
A3: Carnesecchi | B3: Atalanta | C3: P | D3: Por | E3: 26 | F3: 9 | G3: =IFERROR(AVERAGE(I3:AT3),"") | H3: 0
A4: Sportiello | B4: Atalanta | C4: P | D4: Por | E4: 1 | F4: 0 | G4: =IFERROR(AVERAGE(I4:AT4),"") | H4: 0
A5: Vismara | B5: Atalanta | C5: P | D5: Por | E5: 1 | F5: 0 | G5: =IFERROR(AVERAGE(I5:AT5),"") | H5: 0
A6: Ahanor | B6: Atalanta | C6: D | D6: B/Ds/E | E6: 8 | F6: 0 | G6: =IFERROR(AVERAGE(I6:AT6),"") | H6: 0
A7: Bellanova | B7: Atalanta | C7: D | D7: Dd/E | E7: 8 | F7: 0 | G7: =IFERROR(AVERAGE(I7:AT7),"") | H7: 0
A8: Bernasconi | B8: Atalanta | C8: D | D8: Ds/E | E8: 9 | F8: 0 | G8: =IFERROR(AVERAGE(I8:AT8),"") | H8: 0
A9: Hien | B9: Atalanta | C9: D | D9: Dc | E9: 8 | F9: 0 | G9: =IFERROR(AVERAGE(I9:AT9),"") | H9: 0
A10: Kolasinac | B10: Atalanta | C10: D | D10: Ds/Dc | E10: 6 | F10: 0 | G10: =IFERROR(AVERAGE(I10:AT10),"") | H10: 0
A11: Kossounou | B11: Atalanta | C11: D | D11: Dd/Dc | E11: 4 | F11: 0 | G11: =IFERROR(AVERAGE(I11:AT11),"") | H11: 0
A12: Kristensen T. | B12: Atalanta | C12: D | D12: Dd/Dc | E12: 10 | F12: 0 | G12: =IFERROR(AVERAGE(I12:AT12),"") | H12: 0
A13: Scalvini | B13: Atalanta | C13: D | D13: Dc | E13: 14 | F13: 0 | G13: =IFERROR(AVERAGE(I13:AT13),"") | H13: 0
A14: Zappacosta | B14: Atalanta | C14: D | D14: Dd/E | E14: 12 | F14: 0 | G14: =IFERROR(AVERAGE(I14:AT14),"") | H14: 0
... A50: Piccoli | B50: Bologna | C50: A | D50: Pc | E50: 16 | F50: 0 | G50: =IFERROR(AVERAGE(I50:AT50),"") | H50: 0
A51: Caprile | B51: Cagliari | C51: P | D51: Por | E51: 14 | F51: 9 | G51: =IFERROR(AVERAGE(I51:AT51),"") -> 7.1 | H51: 0 | I51: 7.1
A52: Radunovic | B52: Cagliari | C52: P | D52: Por | E52: 1 | F52: 0 | G52: =IFERROR(AVERAGE(I52:AT52),"") | H52: 0
A53: Sherri | B53: Cagliari | C53: P | D53: Por | E53: 1 | F53: 0 | G53: =IFERROR(AVERAGE(I53:AT53),"") | H53: 0
A54: Aurelio | B54: Cagliari | C54: D | D54: Ds/E | E54: 3 | F54: 0 | G54: =IFERROR(AVERAGE(I54:AT54),"") | H54: 0 | I54: sv87
A55: Idrissi R. | B55: Cagliari | C55: D | D55: Ds/E | E55: 4 | F55: 0 | G55: =IFERROR(AVERAGE(I55:AT55),"") | H55: 0
A56: Kofler | B56: Cagliari | C56: D | D56: Dc | E56: 6 | F56: 0 | G56: =IFERROR(AVERAGE(I56:AT56),"") | H56: 0
A57: Mina | B57: Cagliari | C57: D | D57: Dc | E57: 10 | F57: 0 | G57: =IFERROR(AVERAGE(I57:AT57),"") | H57: 0
A58: Obert | B58: Cagliari | C58: D | D58: B/Ds/E | E58: 7 | F58: 0 | G58: =IFERROR(AVERAGE(I58:AT58),"") -> 7.1 | H58: 0 | I58: 7.1
A59: Rodriguez Ju. | B59: Cagliari | C59: D | D59: Ds/Dc | E59: 5 | F59: 0 | G59: =IFERROR(AVERAGE(I59:AT59),"") -> 7.3 | H59: 0 | I59: 7.3
A60: Zappa | B60: Cagliari | C60: D | D60: B/Dd/E | E60: 5 | F60: 0 | G60: =IFERROR(AVERAGE(I60:AT60),"") -> 6.6 | H60: 0 | I60: 6.6
A61: Zè Pedro | B61: Cagliari | C61: D | D61: Dd/Dc | E61: 6 | F61: 0 | G61: =IFERROR(AVERAGE(I61:AT61),"") -> 6.2 | H61: 0 | I61: 6.2
A62: Adopo | B62: Cagliari | C62: C | D62: M/C | E62: 7 | F62: 0 | G62: =IFERROR(AVERAGE(I62:AT62),"") -> 7.1 | H62: 0 | I62: 7.1
A63: Deiola | B63: Cagliari | C63: C | D63: M/C | E63: 4 | F63: 0 | G63: =IFERROR(AVERAGE(I63:AT63),"") -> 7.3 | H63: 0 | I63: 7.3
A64: Fazzini | B64: Cagliari | C64: C | D64: C/T | E64: 10 | F64: 0 | G64: =IFERROR(AVERAGE(I64:AT64),"") -> 6 | H64: 0 | I64: 6
A65: Felici | B65: Cagliari | C65: C | D65: W | E65: 5 | F65: 0 | G65: =IFERROR(AVERAGE(I65:AT65),"") -> 6.4 | H65: 0 | I65: 6.4
A66: Liteta | B66: Cagliari | C66: C | D66: M/C | E66: 1 | F66: 0 | G66: =IFERROR(AVERAGE(I66:AT66),"") | H66: 0
A67: Prati | B67: Cagliari | C67: C | D67: M/C | E67: 4 | F67: 0 | G67: =IFERROR(AVERAGE(I67:AT67),"") | H67: 0
A68: Romano | B68: Cagliari | C68: C | D68: M/C | E68: 6 | F68: 0 | G68: =IFERROR(AVERAGE(I68:AT68),"") -> 8.4 | H68: 0 | I68: 8.4
A69: Winks | B69: Cagliari | C69: C | D69: M/C | E69: 7 | F69: 0 | G69: =IFERROR(AVERAGE(I69:AT69),"") -> 6.8 | H69: 0 | I69: 6.8
A70: Albarracin | B70: Cagliari | C70: A | D70: A | E70: 1 | F70: 0 | G70: =IFERROR(AVERAGE(I70:AT70),"") | H70: 0
A71: Borrelli | B71: Cagliari | C71: A | D71: Pc | E71: 5 | F71: 0 | G71: =IFERROR(AVERAGE(I71:AT71),"") -> 6.8 | H71: 0 | I71: 6.8
A72: Esposito Se. | B72: Cagliari | C72: A | D72: A | E72: 20 | F72: 0 | G72: =IFERROR(AVERAGE(I72:AT72),"") | H72: 0
A73: Kevin Carlos | B73: Cagliari | C73: A | D73: Pc | E73: 24 | F73: 0 | G73: =IFERROR(AVERAGE(I73:AT73),"") | H73: 0
A74: Maldini | B74: Cagliari | C74: A | D74: T/A | E74: 11 | F74: 0 | G74: =IFERROR(AVERAGE(I74:AT74),"") -> 6.8 | H74: 0 | I74: 6.8
A75: Mendy P. | B75: Cagliari | C75: A | D75: Pc | E75: 5 | F75: 0 | G75: =IFERROR(AVERAGE(I75:AT75),"") -> 7.2 | H75: 0 | I75: 7.2
A76: Mutandwa | B76: Cagliari | C76: A | D76: Pc | E76: 8 | F76: 0 | G76: =IFERROR(AVERAGE(I76:AT76),"") | H76: 0 | I76: sv87
...

Sheet medie scorse stagioni
A1: Nome | B1: Sq. | C1: eta | D1: R. | E1: R.MANTRA | G1: media | H1: 26-27 | I1: 25-26 | J1: 24-25 | K1: 23-24 | L1: 22-23 | M1: 21-22 | N1: 20-21 | O1: 19-20 | P1: 18-19 | Q1: 17-18 | R1: 16-17 | S1: 15-16
A3: Carnesecchi | B3: Atalanta | C3: 26 | D3: P | E3: Por | G3: =IFERROR(AVERAGE(I3:U3),"") | H3: =_xlfn.XLOOKUP(A3,Foglio1!A:A,Foglio1!G:G,"")
A4: Sportiello | B4: Atalanta | C4: 34 | D4: P | E4: Por | G4: =IFERROR(AVERAGE(I4:U4),"") | H4: =_xlfn.XLOOKUP(A4,Foglio1!A:A,Foglio1!G:G,"")
A5: Vismara | B5: Atalanta | C5: 23 | D5: P | E5: Por | G5: =IFERROR(AVERAGE(I5:U5),"") | H5: =_xlfn.XLOOKUP(A5,Foglio1!A:A,Foglio1!G:G,"")
A6: Ahanor | B6: Atalanta | C6: 18 | D6: D | E6: B/Ds/E | G6: =IFERROR(AVERAGE(I6:U6),"") | H6: =_xlfn.XLOOKUP(A6,Foglio1!A:A,Foglio1!G:G,"")
A7: Bellanova | B7: Atalanta | C7: 26 | D7: D | E7: Dd/E | G7: =IFERROR(AVERAGE(I7:U7),"") | H7: =_xlfn.XLOOKUP(A7,Foglio1!A:A,Foglio1!G:G,"")
A8: Bernasconi | B8: Atalanta | C8: 23 | D8: D | E8: Ds/E | G8: =IFERROR(AVERAGE(I8:U8),"") | H8: =_xlfn.XLOOKUP(A8,Foglio1!A:A,Foglio1!G:G,"")
A9: Hien | B9: Atalanta | C9: 27 | D9: D | E9: Dc | G9: =IFERROR(AVERAGE(I9:U9),"") | H9: =_xlfn.XLOOKUP(A9,Foglio1!A:A,Foglio1!G:G,"")
A10: Kolasinac | B10: Atalanta | C10: 33 | D10: D | E10: Ds/Dc | G10: =IFERROR(AVERAGE(I10:U10),"") | H10: =_xlfn.XLOOKUP(A10,Foglio1!A:A,Foglio1!G:G,"")
A11: Kossounou | B11: Atalanta | C11: 25 | D11: D | E11: Dd/Dc | G11: =IFERROR(AVERAGE(I11:U11),"") | H11: =_xlfn.XLOOKUP(A11,Foglio1!A:A,Foglio1!G:G,"")
A12: Kristensen T. | B12: Atalanta | C12: 24 | D12: D | E12: Dd/Dc | G12: =IFERROR(AVERAGE(I12:U12),"") | H12: =_xlfn.XLOOKUP(A12,Foglio1!A:A,Foglio1!G:G,"")
A13: Scalvini | B13: Atalanta | C13: 23 | D13: D | E13: Dc | G13: =IFERROR(AVERAGE(I13:U13),"") | H13: =_xlfn.XLOOKUP(A13,Foglio1!A:A,Foglio1!G:G,"")
A14: Zappacosta | B14: Atalanta | C14: 34 | D14: D | E14: Dd/E | G14: =IFERROR(AVERAGE(I14:U14),"") | H14: =_xlfn.XLOOKUP(A14,Foglio1!A:A,Foglio1!G:G,"")
... A174: Ellertsson | B174: Genoa | C174: 24 | D174: C | E174: E/C | G174: =IFERROR(AVERAGE(I174:U174),"") | H174: =_xlfn.XLOOKUP(A174,Foglio1!A:A,Foglio1!G:G,"") -> 6.2
A175: Frendrup | B175: Genoa | C175: 25 | D175: C | E175: M/C | G175: =IFERROR(AVERAGE(I175:U175),"") -> 6.8444444 | H175: =_xlfn.XLOOKUP(A175,Foglio1!A:A,Foglio1!G:G,"") -> 7.3 | I175: 6.6 | J175: 6.9 | K175: 6.9 | L175: 7 | M175: 6.9 | N175: 7.1 | O175: 6.9 | P175: 7 | Q175: 6.3
A176: Meichtry | B176: Genoa | C176: 21 | D176: C | E176: W/T | G176: =IFERROR(AVERAGE(I176:U176),"") | H176: =_xlfn.XLOOKUP(A176,Foglio1!A:A,Foglio1!G:G,"") -> 6.2
A177: Messias | B177: Genoa | C177: 35 | D177: C | E177: W/T | G177: =IFERROR(AVERAGE(I177:U177),"") | H177: =_xlfn.XLOOKUP(A177,Foglio1!A:A,Foglio1!G:G,"") -> 6.8
A178: Sow | B178: Genoa | C178: 29 | D178: C | E178: M/C | G178: =IFERROR(AVERAGE(I178:U178),"") | H178: =_xlfn.XLOOKUP(A178,Foglio1!A:A,Foglio1!G:G,"") -> 6.5
A179: Traorè Hj. | B179: Genoa | C179: 26 | D179: C | E179: W/T | G179: =IFERROR(AVERAGE(I179:U179),"") | H179: =_xlfn.XLOOKUP(A179,Foglio1!A:A,Foglio1!G:G,"")
A180: Venturino | B180: Genoa | C180: 20 | D180: C | E180: W | G180: =IFERROR(AVERAGE(I180:U180),"") | H180: =_xlfn.XLOOKUP(A180,Foglio1!A:A,Foglio1!G:G,"")
A181: Colombo | B181: Genoa | C181: 24 | D181: A | E181: Pc | G181: =IFERROR(AVERAGE(I181:U181),"") | H181: =_xlfn.XLOOKUP(A181,Foglio1!A:A,Foglio1!G:G,"") -> 6
A182: Havel | B182: Genoa | C182: 23 | D182: A | E182: Pc | G182: =IFERROR(AVERAGE(I182:U182),"") | H182: =_xlfn.XLOOKUP(A182,Foglio1!A:A,Foglio1!G:G,"")
A183: Vitinha O. | B183: Genoa | C183: 26 | D183: A | E183: A | G183: =IFERROR(AVERAGE(I183:U183),"") | H183: =_xlfn.XLOOKUP(A183,Foglio1!A:A,Foglio1!G:G,"") -> 5.3
A184: Di Gennaro | B184: Inter | C184: 33 | D184: P | E184: Por | G184: =IFERROR(AVERAGE(I184:U184),"") | H184: =_xlfn.XLOOKUP(A184,Foglio1!A:A,Foglio1!G:G,"")
A185: Martinez Jo. | B185: Inter | C185: 28 | D185: P | E185: Por | G185: =IFERROR(AVERAGE(I185:U185),"") | H185: =_xlfn.XLOOKUP(A185,Foglio1!A:A,Foglio1!G:G,"") -> 6.5
A186: Provedel | B186: Inter | C186: 32 | D186: P | E186: Por | G186: =IFERROR(AVERAGE(I186:U186),"") | H186: =_xlfn.XLOOKUP(A186,Foglio1!A:A,Foglio1!G:G,"")
A187: Akanji | B187: Inter | C187: 31 | D187: D | E187: Dc | G187: =IFERROR(AVERAGE(I187:U187),"") | H187: =_xlfn.XLOOKUP(A187,Foglio1!A:A,Foglio1!G:G,"") -> 7.2
... A361: Santos A. | B361: Napoli | C361: 24 | D361: A | E361: W/A | G361: =IFERROR(AVERAGE(I361:U361),"") | H361: =_xlfn.XLOOKUP(A361,Foglio1!A:A,Foglio1!G:G,"") -> 6.6
A362: Corvi | B362: Parma | C362: 25 | D362: P | E362: Por | G362: =IFERROR(AVERAGE(I362:U362),"") -> 6.9333333 | H362: =_xlfn.XLOOKUP(A362,Foglio1!A:A,Foglio1!G:G,"") -> 6.5 | I362: 6.9 | K362: 7.3 | L362: 6.6
A363: Daffara | B363: Parma | C363: 22 | D363: P | E363: Por | G363: =IFERROR(AVERAGE(I363:U363),"") | H363: =_xlfn.XLOOKUP(A363,Foglio1!A:A,Foglio1!G:G,"")
A364: Britschgi | B364: Parma | C364: 20 | D364: D | E364: Dd/Ds/E | G364: =IFERROR(AVERAGE(I364:U364),"") -> 6.25 | H364: =_xlfn.XLOOKUP(A364,Foglio1!A:A,Foglio1!G:G,"") | I364: 6.1 | J364: 6.4
A365: Carboni F. | B365: Parma | C365: 23 | D365: D | E365: Ds/E | G365: =IFERROR(AVERAGE(I365:U365),"") -> 6.65 | H365: =_xlfn.XLOOKUP(A365,Foglio1!A:A,Foglio1!G:G,"") | I365: 6.35 | J365: 6.6 | K365: 6.9 | L365: 6.7 | M365: 6.7
A366: Delprato | B366: Parma | C366: 27 | D366: D | E366: B/Dd/E | G366: =IFERROR(AVERAGE(I366:U366),"") -> 6.7428571 | H366: =_xlfn.XLOOKUP(A366,Foglio1!A:A,Foglio1!G:G,"") -> 6.3 | I366: 6.4 | J366: 6.7 | K366: 7 | L366: 7 | M366: 6.8 | N366: 6.7 | O366: 6.6
A367: Ndiaye | B367: Parma | C367: 24 | D367: D | E367: Dc | G367: =IFERROR(AVERAGE(I367:U367),"") -> 6.85 | H367: =_xlfn.XLOOKUP(A367,Foglio1!A:A,Foglio1!G:G,"") -> 5.6 | I367: 6.2 | J367: 7 | K367: 7.1 | L367: 7.1
A368: Troilo | B368: Parma | C368: 23 | D368: D | E368: Dc | G368: =IFERROR(AVERAGE(I368:U368),"") -> 6.8 | H368: =_xlfn.XLOOKUP(A368,Foglio1!A:A,Foglio1!G:G,"") -> 6.7 | I368: 6.7 | J368: 6.8 | K368: 6.9
A369: Valenti | B369: Parma | C369: 27 | D369: D | E369: Dc | G369: =IFERROR(AVERAGE(I369:U369),"") | H369: =_xlfn.XLOOKUP(A369,Foglio1!A:A,Foglio1!G:G,"")
A370: Valeri | B370: Parma | C370: 28 | D370: D | E370: Ds/E | G370: =IFERROR(AVERAGE(I370:U370),"") -> 6.85 | H370: =_xlfn.XLOOKUP(A370,Foglio1!A:A,Foglio1!G:G,"") -> 6.8 | I370: 6.8 | J370: 6.8 | K370: 6.7 | L370: 6.6 | M370: 7.1 | N370: 7.1
A371: Almqvist | B371: Parma | C371: 27 | D371: C | E371: W/A | G371: =IFERROR(AVERAGE(I371:U371),"") -> 6.8571429 | H371: =_xlfn.XLOOKUP(A371,Foglio1!A:A,Foglio1!G:G,"") -> 6.3 | I371: 6.4 | J371: 6.6 | K371: 6.8 | L371: 7.1 | M371: 7.3 | N371: 6.8 | Q371: 7
A372: Bernabè | B372: Parma | C372: 25 | D372: C | E372: C | G372: =IFERROR(AVERAGE(I372:U372),"") -> 7.2 | H372: =_xlfn.XLOOKUP(A372,Foglio1!A:A,Foglio1!G:G,"") -> 6.6 | I372: 6.9 | J372: 7 | K372: 7.3 | L372: 7.2 | M372: 7.6
A373: Cremaschi | B373: Parma | C373: 21 | D373: C | E373: E/C | G373: =IFERROR(AVERAGE(I373:U373),"") -> 6.7333333 | H373: =_xlfn.XLOOKUP(A373,Foglio1!A:A,Foglio1!G:G,"") | I373: 6.4 | J373: 6.9 | K373: 6.9
...

Sheet Foglio6
E1: rig | F1: puniz | G1: da bonus
A3: Ahanor | B3: 8 | C3: atalanta
A4: Bellanova | B4: 5 | C4: atalanta
A5: Bernasconi | B5: 11 | C5: atalanta | D5: ahanor
A6: Carnesecchi | B6: 18 | C6: atalanta
A7: De Ketelaere | B7: 17 | C7: atalanta | F7: 3
A8: De Roon | B8: 5 | C8: atalanta
A9: Ederson D.S. | B9: 18 | C9: atalanta
A10: Gaetano | B10: 14.5 | C10: atalanta | F10: 1
A11: Hien | B11: 2.5 | C11: atalanta | D11: infortunato autunno
A12: Kolasinac | B12: 1.5 | C12: atalanta
A13: Kossounou | B13: 1 | C13: atalanta
A14: Kristensen T. | B14: 16 | C14: atalanta | D14: hien
A15: Krstovic | B15: 4 | C15: atalanta | E15: 2
A16: Pasalic | B16: 7 | C16: atalanta
A17: Raspadori | B17: 15 | C17: atalanta
A18: Samardzic | B18: 13 | C18: atalanta | D18: pasalic | E18: 1 | F18: 2
A19: Scalvini | B19: 16.5 | C19: atalanta
A20: Scamacca | B20: 14.5 | C20: atalanta | D20: krstovic | E20: 3
A21: Zalewski | B21: 1 | C21: atalanta
A22: Zappacosta | B22: 14 | C22: atalanta | D22: bellanova
A23: Amondarain | B23: 3.5 | C23: bologna
A24: Bernardeschi | B24: 16 | C24: bologna | D24: amondarain-odgaard | E24: 2 | F24: 2
A25: Cambiaghi | B25: 1 | C25: bologna
A26: Casale | B26: 1 | C26: bologna
A27: Dovbyk | B27: 13.5 | C27: bologna | D27: piccoli | E27: 1
A28: Ferguson | B28: 16 | C28: bologna
A29: Heggem | B29: 18 | C29: bologna
A30: Helland | B30: 4 | C30: bologna
A31: Holm | B31: 3 | C31: bologna
A32: Miranda J. | B32: 18 | C32: bologna | F32: 1
A33: Moro L. | B33: 13.5 | C33: bologna
A34: Odgaard | B34: 3 | C34: bologna
A35: Orsolini | B35: 19 | C35: bologna | E35: 3 | F35: 3
A36: Piccoli | B36: 7 | C36: bologna
A37: Pobega | B37: 4.5 | C37: bologna
A38: Rowe | B38: 15 | C38: bologna | D38: cambiaghi
A39: Skorupski | B39: 18 | C39: bologna
A40: Vitik | B40: 14 | C40: bologna | D40: casale
A41: Zortea | B41: 16 | C41: bologna
...

Sheet porta
A1: Svilar | B1: Roma | C1: 27 | D1: P | E1: Por | F1: 33
A2: Martinez Jo. | B2: Inter | C2: 28 | D2: P | E2: Por | F2: 32
A3: Butez | B3: Como | C3: 31 | D3: P | E3: Por | F3: 28
A4: Vicario | B4: Juventus | C4: 30 | D4: P | E4: Por | F4: 28
A5: Carnesecchi | B5: Atalanta | C5: 26 | D5: P | E5: Por | F5: 26
A6: Maignan | B6: Milan | C6: 31 | D6: P | E6: Por | F6: 25
A7: De Gea | B7: Fiorentina | C7: 36 | D7: P | E7: Por | F7: 23
A8: Meret | B8: Napoli | C8: 29 | D8: P | E8: Por | F8: 23
A9: Skorupski | B9: Bologna | C9: 35 | D9: P | E9: Por | F9: 19
A10: Mandas | B10: Lazio | C10: 25 | D10: P | E10: Por | F10: 15
A11: Okoye | B11: Udinese | C11: 27 | D11: P | E11: Por | F11: 15
A12: Caprile | B12: Cagliari | C12: 25 | D12: P | E12: Por | F12: 14
... A63: Vismara | B63: Atalanta | C63: 23 | D63: P | E63: Por | F63: 1

Sheet dif
A1: nome | B1: sq | C1: eta | D1: ruolo | E1: mantra | F1: quit 1000 | H1: titolare | I1: rigori e piazzati | J1: affidablita | L1: 1 credito | M1: prima | N1: seconda | O1: terza | R1: Dimarco | T1: Solet
R2: Molina N. | T2: Rrhamani
A3: Dimarco | B3: Inter | C3: 29 | D3: D | E3: E/W | F3: 133 | G3: 0 | H3: =_xlfn.XLOOKUP(A3,Foglio6!A:A,Foglio6!B:B,0) -> 19 | I3: =SUM(_xlfn.XLOOKUP(A3,Foglio6!A:A,Foglio6!E:E,0),_xlfn.XLOOKUP(A3,Foglio6!A:A,Foglio6!F:F,0)) -> 2 | J3: 0 | K3: 0 | L3: 3 | M3: 1 | R3: Wesley | T3: Ndicka
A4: Tiago Gabriel | B4: Lecce | C4: 22 | D4: D | E4: Dc | F4: 9 | H4: =_xlfn.XLOOKUP(A4,Foglio6!A:A,Foglio6!B:B,0) -> 19 | I4: =SUM(_xlfn.XLOOKUP(A4,Foglio6!A:A,Foglio6!E:E,0),_xlfn.XLOOKUP(A4,Foglio6!A:A,Foglio6!F:F,0)) -> 0 | L4: 1 | R4: Akanji | T4: Bisseck
A5: Molina N. | B5: Roma | C5: 28 | D5: D | E5: E | F5: 44 | G5: 0 | H5: =_xlfn.XLOOKUP(A5,Foglio6!A:A,Foglio6!B:B,0) -> 18 | I5: =SUM(_xlfn.XLOOKUP(A5,Foglio6!A:A,Foglio6!E:E,0),_xlfn.XLOOKUP(A5,Foglio6!A:A,Foglio6!F:F,0)) -> 0 | J5: 0 | K5: 0 | L5: 3 | M5: 1 | R5: Mancini | T5: Ramon
A6: Wesley | B6: Roma | C6: 23 | D6: D | E6: E | F6: 42 | G6: 0 | H6: =_xlfn.XLOOKUP(A6,Foglio6!A:A,Foglio6!B:B,0) -> 18 | I6: =SUM(_xlfn.XLOOKUP(A6,Foglio6!A:A,Foglio6!E:E,0),_xlfn.XLOOKUP(A6,Foglio6!A:A,Foglio6!F:F,0)) -> 0 | J6: 0 | K6: 0 | L6: 3 | M6: 1 | R6: Kalulu | T6: vojvoda
A7: Akanji | B7: Inter | C7: 31 | D7: D | E7: Dc | F7: 28 | G7: 0 | H7: =_xlfn.XLOOKUP(A7,Foglio6!A:A,Foglio6!B:B,0) -> 18 | I7: =SUM(_xlfn.XLOOKUP(A7,Foglio6!A:A,Foglio6!E:E,0),_xlfn.XLOOKUP(A7,Foglio6!A:A,Foglio6!F:F,0)) -> 0 | J7: 0 | K7: 0 | L7: 2 | M7: 1 | R7: Bastoni
A8: Mancini | B8: Roma | C8: 30 | D8: D | E8: Dc | F8: 25 | G8: 0 | H8: =_xlfn.XLOOKUP(A8,Foglio6!A:A,Foglio6!B:B,0) -> 18 | I8: =SUM(_xlfn.XLOOKUP(A8,Foglio6!A:A,Foglio6!E:E,0),_xlfn.XLOOKUP(A8,Foglio6!A:A,Foglio6!F:F,0)) -> 0 | L8: 2 | M8: 1 | R8: Chalobah T.
A9: Bastoni | B9: Inter | C9: 27 | D9: D | E9: Dc | F9: 22 | G9: 0 | H9: =_xlfn.XLOOKUP(A9,Foglio6!A:A,Foglio6!B:B,0) -> 18 | I9: =SUM(_xlfn.XLOOKUP(A9,Foglio6!A:A,Foglio6!E:E,0),_xlfn.XLOOKUP(A9,Foglio6!A:A,Foglio6!F:F,0)) -> 0 | L9: 2 | M9: 1 | R9: Spence
A10: Bremer | B10: Juventus | C10: 29 | D10: D | E10: Dc | F10: 25 | G10: 0 | H10: =_xlfn.XLOOKUP(A10,Foglio6!A:A,Foglio6!B:B,0) -> 18 | I10: =SUM(_xlfn.XLOOKUP(A10,Foglio6!A:A,Foglio6!E:E,0),_xlfn.XLOOKUP(A10,Foglio6!A:A,Foglio6!F:F,0)) -> 0 | L10: 2 | R10: Bremer
A11: Pavlovic | B11: Milan | C11: 25 | D11: D | E11: Dc | F11: 24 | G11: 0 | H11: =_xlfn.XLOOKUP(A11,Foglio6!A:A,Foglio6!B:B,0) -> 18 | I11: =SUM(_xlfn.XLOOKUP(A11,Foglio6!A:A,Foglio6!E:E,0),_xlfn.XLOOKUP(A11,Foglio6!A:A,Foglio6!F:F,0)) -> 0 | L11: 1
A12: Rrahmani | B12: Napoli | C12: 32 | D12: D | E12: Dc | F12: 24 | G12: 0 | H12: =_xlfn.XLOOKUP(A12,Foglio6!A:A,Foglio6!B:B,0) -> 18 | I12: =SUM(_xlfn.XLOOKUP(A12,Foglio6!A:A,Foglio6!E:E,0),_xlfn.XLOOKUP(A12,Foglio6!A:A,Foglio6!F:F,0)) -> 0 | J12: 0 | K12: 0 | L12: 1
A13: Solet | B13: Udinese | C13: 26 | D13: D | E13: Dc | F13: 23 | G13: 0 | H13: =_xlfn.XLOOKUP(A13,Foglio6!A:A,Foglio6!B:B,0) -> 18 | I13: =SUM(_xlfn.XLOOKUP(A13,Foglio6!A:A,Foglio6!E:E,0),_xlfn.XLOOKUP(A13,Foglio6!A:A,Foglio6!F:F,0)) -> 2 | L13: 2
A14: N'Dicka | B14: Roma | C14: 27 | D14: D | E14: Dc | F14: 22 | H14: =_xlfn.XLOOKUP(A14,Foglio6!A:A,Foglio6!B:B,0) -> 18 | I14: =SUM(_xlfn.XLOOKUP(A14,Foglio6!A:A,Foglio6!E:E,0),_xlfn.XLOOKUP(A14,Foglio6!A:A,Foglio6!F:F,0)) -> 0 | L14: 1
A15: Di Lorenzo | B15: Napoli | C15: 33 | D15: D | E15: Dd/E | F15: 20 | H15: =_xlfn.XLOOKUP(A15,Foglio6!A:A,Foglio6!B:B,0) -> 18 | I15: =SUM(_xlfn.XLOOKUP(A15,Foglio6!A:A,Foglio6!E:E,0),_xlfn.XLOOKUP(A15,Foglio6!A:A,Foglio6!F:F,0)) -> 0 | L15: 1
A16: Ostigard | B16: Genoa | C16: 27 | D16: D | E16: Dc | F16: 20 | H16: =_xlfn.XLOOKUP(A16,Foglio6!A:A,Foglio6!B:B,0) -> 18 | I16: =SUM(_xlfn.XLOOKUP(A16,Foglio6!A:A,Foglio6!E:E,0),_xlfn.XLOOKUP(A16,Foglio6!A:A,Foglio6!F:F,0)) -> 2 | L16: 2
A17: Vasquez | B17: Genoa | C17: 28 | D17: D | E17: Ds/Dc | F17: 17 | H17: =_xlfn.XLOOKUP(A17,Foglio6!A:A,Foglio6!B:B,0) -> 18 | I17: =SUM(_xlfn.XLOOKUP(A17,Foglio6!A:A,Foglio6!E:E,0),_xlfn.XLOOKUP(A17,Foglio6!A:A,Foglio6!F:F,0)) -> 0 | L17: 2
A18: Gila | B18: Milan | C18: 26 | D18: D | E18: Dc | F18: 16 | H18: =_xlfn.XLOOKUP(A18,Foglio6!A:A,Foglio6!B:B,0) -> 18 | I18: =SUM(_xlfn.XLOOKUP(A18,Foglio6!A:A,Foglio6!E:E,0),_xlfn.XLOOKUP(A18,Foglio6!A:A,Foglio6!F:F,0)) -> 0 | L18: 1
A19: Cambiaso | B19: Juventus | C19: 26 | D19: D | E19: Dd/Ds/E | F19: 14 | H19: =_xlfn.XLOOKUP(A19,Foglio6!A:A,Foglio6!B:B,0) -> 18 | I19: =SUM(_xlfn.XLOOKUP(A19,Foglio6!A:A,Foglio6!E:E,0),_xlfn.XLOOKUP(A19,Foglio6!A:A,Foglio6!F:F,0)) -> 0 | L19: 1
A20: Dragusin | B20: Fiorentina | C20: 24 | D20: D | E20: Dc | F20: 14 | H20: =_xlfn.XLOOKUP(A20,Foglio6!A:A,Foglio6!B:B,0) -> 18 | I20: =SUM(_xlfn.XLOOKUP(A20,Foglio6!A:A,Foglio6!E:E,0),_xlfn.XLOOKUP(A20,Foglio6!A:A,Foglio6!F:F,0)) -> 0 | L20: 1
A21: Gabbia | B21: Milan | C21: 27 | D21: D | E21: Dc | F21: 13 | H21: =_xlfn.XLOOKUP(A21,Foglio6!A:A,Foglio6!B:B,0) -> 18 | I21: =SUM(_xlfn.XLOOKUP(A21,Foglio6!A:A,Foglio6!E:E,0),_xlfn.XLOOKUP(A21,Foglio6!A:A,Foglio6!F:F,0)) -> 0 | L21: 1
A22: Miranda J. | B22: Bologna | C22: 26 | D22: D | E22: Ds/E | F22: 12 | H22: =_xlfn.XLOOKUP(A22,Foglio6!A:A,Foglio6!B:B,0) -> 18 | I22: =SUM(_xlfn.XLOOKUP(A22,Foglio6!A:A,Foglio6!E:E,0),_xlfn.XLOOKUP(A22,Foglio6!A:A,Foglio6!F:F,0)) -> 1 | L22: 1
A23: Delprato | B23: Parma | C23: 27 | D23: D | E23: B/Dd/E | F23: 11 | H23: =_xlfn.XLOOKUP(A23,Foglio6!A:A,Foglio6!B:B,0) -> 18 | I23: =SUM(_xlfn.XLOOKUP(A23,Foglio6!A:A,Foglio6!E:E,0),_xlfn.XLOOKUP(A23,Foglio6!A:A,Foglio6!F:F,0)) -> 0 | L23: 1
A24: Doekhi | B24: Lazio | C24: 28 | D24: D | E24: Dc | F24: 11 | H24: =_xlfn.XLOOKUP(A24,Foglio6!A:A,Foglio6!B:B,0) -> 18 | I24: =SUM(_xlfn.XLOOKUP(A24,Foglio6!A:A,Foglio6!E:E,0),_xlfn.XLOOKUP(A24,Foglio6!A:A,Foglio6!F:F,0)) -> 0 | L24: 1
A25: Norton-Cuffy | B25: Genoa | C25: 22 | D25: D | E25: Dd/E | F25: 11 | H25: =_xlfn.XLOOKUP(A25,Foglio6!A:A,Foglio6!B:B,0) -> 18 | I25: =SUM(_xlfn.XLOOKUP(A25,Foglio6!A:A,Foglio6!E:E,0),_xlfn.XLOOKUP(A25,Foglio6!A:A,Foglio6!F:F,0)) -> 0 | L25: 1
... A32: Gallo | B32: Lecce | C32: 26 | D32: D | E32: Ds/E | F32: 7 | H32: =_xlfn.XLOOKUP(A32,Foglio6!A:A,Foglio6!B:B,0) -> 18 | I32: =SUM(_xlfn.XLOOKUP(A32,Foglio6!A:A,Foglio6!E:E,0),_xlfn.XLOOKUP(A32,Foglio6!A:A,Foglio6!F:F,0)) -> 1 | L32: 2
A33: Marcandalli | B33: Genoa | C33: 24 | D33: D | E33: Dc | F33: 7 | H33: =_xlfn.XLOOKUP(A33,Foglio6!A:A,Foglio6!B:B,0) -> 18 | I33: =SUM(_xlfn.XLOOKUP(A33,Foglio6!A:A,Foglio6!E:E,0),_xlfn.XLOOKUP(A33,Foglio6!A:A,Foglio6!F:F,0)) -> 0
A34: Obert | B34: Cagliari | C34: 24 | D34: D | E34: B/Ds/E | F34: 7 | H34: =_xlfn.XLOOKUP(A34,Foglio6!A:A,Foglio6!B:B,0) -> 18 | I34: =SUM(_xlfn.XLOOKUP(A34,Foglio6!A:A,Foglio6!E:E,0),_xlfn.XLOOKUP(A34,Foglio6!A:A,Foglio6!F:F,0)) -> 0 | L34: 1
A35: Pedersen | B35: Torino | C35: 26 | D35: D | E35: Dd/E | F35: 7 | H35: =_xlfn.XLOOKUP(A35,Foglio6!A:A,Foglio6!B:B,0) -> 18 | I35: =SUM(_xlfn.XLOOKUP(A35,Foglio6!A:A,Foglio6!E:E,0),_xlfn.XLOOKUP(A35,Foglio6!A:A,Foglio6!F:F,0)) -> 0 | L35: 1
A36: Comuzzo | B36: Torino | C36: 21 | D36: D | E36: Dc | F36: 6 | H36: =_xlfn.XLOOKUP(A36,Foglio6!A:A,Foglio6!B:B,0) -> 18 | I36: =SUM(_xlfn.XLOOKUP(A36,Foglio6!A:A,Foglio6!E:E,0),_xlfn.XLOOKUP(A36,Foglio6!A:A,Foglio6!F:F,0)) -> 0
A37: Kamara H. | B37: Udinese | C37: 32 | D37: D | E37: Ds/E | F37: 6 | H37: =_xlfn.XLOOKUP(A37,Foglio6!A:A,Foglio6!B:B,0) -> 18 | I37: =SUM(_xlfn.XLOOKUP(A37,Foglio6!A:A,Foglio6!E:E,0),_xlfn.XLOOKUP(A37,Foglio6!A:A,Foglio6!F:F,0)) -> 0
A38: Veiga D. | B38: Lecce | C38: 24 | D38: D | E38: Dd/E | F38: 6 | H38: =_xlfn.XLOOKUP(A38,Foglio6!A:A,Foglio6!B:B,0) -> 18 | I38: =SUM(_xlfn.XLOOKUP(A38,Foglio6!A:A,Foglio6!E:E,0),_xlfn.XLOOKUP(A38,Foglio6!A:A,Foglio6!F:F,0)) -> 0 | L38: 1
A39: Carboni A. | B39: Monza | C39: 25 | D39: D | E39: Ds/Dc | F39: 5 | H39: =_xlfn.XLOOKUP(A39,Foglio6!A:A,Foglio6!B:B,0) -> 18 | I39: =SUM(_xlfn.XLOOKUP(A39,Foglio6!A:A,Foglio6!E:E,0),_xlfn.XLOOKUP(A39,Foglio6!A:A,Foglio6!F:F,0)) -> 0
A40: Kabasele | B40: Udinese | C40: 35 | D40: D | E40: Dc | F40: 5 | H40: =_xlfn.XLOOKUP(A40,Foglio6!A:A,Foglio6!B:B,0) -> 18 | I40: =SUM(_xlfn.XLOOKUP(A40,Foglio6!A:A,Foglio6!E:E,0),_xlfn.XLOOKUP(A40,Foglio6!A:A,Foglio6!F:F,0)) -> 0 | L40: 1
A41: Schingtienne | B41: Venezia | C41: 24 | D41: D | E41: Dc | F41: 4 | H41: =_xlfn.XLOOKUP(A41,Foglio6!A:A,Foglio6!B:B,0) -> 18 | I41: =SUM(_xlfn.XLOOKUP(A41,Foglio6!A:A,Foglio6!E:E,0),_xlfn.XLOOKUP(A41,Foglio6!A:A,Foglio6!F:F,0)) -> 0 | L41: 1
A42: Troilo | B42: Parma | C42: 23 | D42: D | E42: Dc | F42: 4 | H42: =_xlfn.XLOOKUP(A42,Foglio6!A:A,Foglio6!B:B,0) -> 18 | I42: =SUM(_xlfn.XLOOKUP(A42,Foglio6!A:A,Foglio6!E:E,0),_xlfn.XLOOKUP(A42,Foglio6!A:A,Foglio6!F:F,0)) -> 0 | L42: 1
A43: Ramon | B43: Como | C43: 21 | D43: D | E43: Dc | F43: 16 | H43: =_xlfn.XLOOKUP(A43,Foglio6!A:A,Foglio6!B:B,0) -> 17.5 | I43: =SUM(_xlfn.XLOOKUP(A43,Foglio6!A:A,Foglio6!E:E,0),_xlfn.XLOOKUP(A43,Foglio6!A:A,Foglio6!F:F,0)) -> 0 | L43: 2
A44: Kalulu | B44: Juventus | C44: 26 | D44: D | E44: Dd/Dc | F44: 23 | G44: 0 | H44: =_xlfn.XLOOKUP(A44,Foglio6!A:A,Foglio6!B:B,0) -> 17 | I44: =SUM(_xlfn.XLOOKUP(A44,Foglio6!A:A,Foglio6!E:E,0),_xlfn.XLOOKUP(A44,Foglio6!A:A,Foglio6!F:F,0)) -> 0 | J44: 0 | K44: 0 | L44: 2 | M44: 1
A45: Couto | B45: Como | C45: 24 | D45: D | E45: Dd/E | F45: 14 | H45: =_xlfn.XLOOKUP(A45,Foglio6!A:A,Foglio6!B:B,0) -> 17 | I45: =SUM(_xlfn.XLOOKUP(A45,Foglio6!A:A,Foglio6!E:E,0),_xlfn.XLOOKUP(A45,Foglio6!A:A,Foglio6!F:F,0)) -> 0 | L45: 2
A46: Mina | B46: Cagliari | C46: 32 | D46: D | E46: Dc | F46: 10 | H46: =_xlfn.XLOOKUP(A46,Foglio6!A:A,Foglio6!B:B,0) -> 17 | I46: =SUM(_xlfn.XLOOKUP(A46,Foglio6!A:A,Foglio6!E:E,0),_xlfn.XLOOKUP(A46,Foglio6!A:A,Foglio6!F:F,0)) -> 1
...

Sheet ipotetica rossa
A1: rosa
A3: p | B3: carnesecchi | C3: 35 | D3: 35 | E3: =SUM(C3:C5) -> 46 | G3: =SUM(E3,E7,E16,E25) -> 476 | I3: =SUM(500-G3) -> 24
A4: p | B4: bijlow | C4: 10 | D4: 9
A5: p | B5: sportiello/stolz | C5: 1 | D5: 1 | G5: =SUM(D3:D30) -> 541 | I5: =SUM(500-G5) -> -41
A7: d | B7: molina | C7: 30 | D7: 35 | E7: =SUM(C7:C14) -> 59
A8: d | B8: couto | C8: 10 | D8: 10
A9: d | B9: kaiki | C9: 10 | D9: 10
A10: d | B10: valdepenas | C10: 5 | D10: 5
A11: d | B11: gallo | C11: 1 | D11: 1
A12: d | B12: marcandalli | C12: 1 | D12: 1
A13: d | B13: monterisi | C13: 1 | D13: 1
A14: d | B14: birindelli | C14: 1 | D14: 1
A16: c | B16: atta/gudmundsson | C16: 40 | D16: 40 | E16: =SUM(C16:C23) -> 114
A17: c | B17: mc kennie | C17: 25 | D17: 25
A18: c | B18: ederson | C18: 30 | D18: 30
A19: c | B19: ekkelenkamp | C19: 15 | D19: 15
A20: c | B20: schmid/sow/pierotti | C20: 1 | D20: 1
A21: c | B21: busio | C21: 1 | D21: 1
A22: c | B22: basic | C22: 1 | D22: 1
A23: c | B23: akinsanmiro | C23: 1 | D23: 2
A25: a | B25: malen | C25: 180 | D25: 200 | E25: =SUM(C25:C30) -> 257
A26: a | B26: simeone | C26: 70 | D26: 73
A27: a | B27: elphege | C27: 1 | D27: 9
A28: a | B28: vitinha | C28: 1 | D28: 13
A29: a | B29: ndri | C29: 4 | D29: 1
A30: a | B30: yeboah | C30: 1 | D30: 21

Sheet cc
A1: nome | B1: sq | C1: eta | D1: ruolo | E1: mantra | F1: quit 1000 | H1: titolare | I1: rigori e piazzati | J1: affidablita | L1: 1 credito | O1: 70-80 | P1: Paz N. | R1: Barella | S1: 40
P2: Atta | R2: Mora
A3: Paz N. | B3: Como | C3: 22 | D3: C | E3: T/A | F3: 125 | G3: 0 | H3: =_xlfn.XLOOKUP(A3,Foglio6!A:A,Foglio6!B:B,0) -> 19 | I3: =SUM(_xlfn.XLOOKUP(A3,Foglio6!A:A,Foglio6!E:E,0),_xlfn.XLOOKUP(A3,Foglio6!A:A,Foglio6!F:F,0)) -> 4 | J3: 0 | K3: 0 | L3: 2 | P3: Calhanoglu | R3: De Bruyne
A4: McTominay | B4: Napoli | C4: 30 | D4: C | E4: C/T | F4: 120 | G4: 0 | H4: =_xlfn.XLOOKUP(A4,Foglio6!A:A,Foglio6!B:B,0) -> 19 | I4: =SUM(_xlfn.XLOOKUP(A4,Foglio6!A:A,Foglio6!E:E,0),_xlfn.XLOOKUP(A4,Foglio6!A:A,Foglio6!F:F,0)) -> 0 | J4: 0 | K4: 0 | L4: 2 | P4: Rowe | R4: Da Cunha
A5: Calhanoglu | B5: Inter | C5: 32 | D5: C | E5: M/C | F5: 115 | G5: 0 | H5: =_xlfn.XLOOKUP(A5,Foglio6!A:A,Foglio6!B:B,0) -> 19 | I5: =SUM(_xlfn.XLOOKUP(A5,Foglio6!A:A,Foglio6!E:E,0),_xlfn.XLOOKUP(A5,Foglio6!A:A,Foglio6!F:F,0)) -> 6 | J5: 0 | K5: 0 | L5: 2 | P5: McTominay | R5: Zaniolo
A6: Orsolini | B6: Bologna | C6: 29 | D6: C | E6: W/A | F6: 100 | G6: 0 | H6: =_xlfn.XLOOKUP(A6,Foglio6!A:A,Foglio6!B:B,0) -> 19 | I6: =SUM(_xlfn.XLOOKUP(A6,Foglio6!A:A,Foglio6!E:E,0),_xlfn.XLOOKUP(A6,Foglio6!A:A,Foglio6!F:F,0)) -> 6 | J6: 0 | K6: 0 | L6: 2 | P6: Orsolini | R6: Ekkelenkamp
A7: Rabiot | B7: Milan | C7: 31 | D7: C | E7: C/T | F7: 64 | G7: 0 | H7: =_xlfn.XLOOKUP(A7,Foglio6!A:A,Foglio6!B:B,0) -> 19 | I7: =SUM(_xlfn.XLOOKUP(A7,Foglio6!A:A,Foglio6!E:E,0),_xlfn.XLOOKUP(A7,Foglio6!A:A,Foglio6!F:F,0)) -> 0 | L7: 2 | P7: Pulisic | R7: Gudmundsson
A8: Zaniolo | B8: Udinese | C8: 27 | D8: C | E8: T/A | F8: 50 | H8: =_xlfn.XLOOKUP(A8,Foglio6!A:A,Foglio6!B:B,0) -> 19 | I8: =SUM(_xlfn.XLOOKUP(A8,Foglio6!A:A,Foglio6!E:E,0),_xlfn.XLOOKUP(A8,Foglio6!A:A,Foglio6!F:F,0)) -> 4 | L8: 2 | P8: Rabiot | R8: Mc Kennie
A9: Barella | B9: Inter | C9: 29 | D9: C | E9: C | F9: 40 | H9: =_xlfn.XLOOKUP(A9,Foglio6!A:A,Foglio6!B:B,0) -> 19 | I9: =SUM(_xlfn.XLOOKUP(A9,Foglio6!A:A,Foglio6!E:E,0),_xlfn.XLOOKUP(A9,Foglio6!A:A,Foglio6!F:F,0)) -> 0 | L9: 2 | P9: Mastantuono | R9: Zaccagni
A10: Modric | B10: Milan | C10: 41 | D10: C | E10: M/C | F10: 25 | H10: =_xlfn.XLOOKUP(A10,Foglio6!A:A,Foglio6!B:B,0) -> 19 | I10: =SUM(_xlfn.XLOOKUP(A10,Foglio6!A:A,Foglio6!E:E,0),_xlfn.XLOOKUP(A10,Foglio6!A:A,Foglio6!F:F,0)) -> 4 | L10: 1 | P10: Baturina | R10: Vlasic
A11: Ekkelenkamp | B11: Udinese | C11: 26 | D11: C | E11: C/T | F11: 21 | H11: =_xlfn.XLOOKUP(A11,Foglio6!A:A,Foglio6!B:B,0) -> 19 | I11: =SUM(_xlfn.XLOOKUP(A11,Foglio6!A:A,Foglio6!E:E,0),_xlfn.XLOOKUP(A11,Foglio6!A:A,Foglio6!F:F,0)) -> 2 | L11: 2
A12: Basic | B12: Venezia | C12: 30 | D12: C | E12: M/C | F12: 10 | H12: =_xlfn.XLOOKUP(A12,Foglio6!A:A,Foglio6!B:B,0) -> 19 | I12: =SUM(_xlfn.XLOOKUP(A12,Foglio6!A:A,Foglio6!E:E,0),_xlfn.XLOOKUP(A12,Foglio6!A:A,Foglio6!F:F,0)) -> 0 | L12: 1 | O12: 20 | P12: Conceicao | S12: 10
A13: Lobotka | B13: Napoli | C13: 32 | D13: C | E13: M/C | F13: 10 | H13: =_xlfn.XLOOKUP(A13,Foglio6!A:A,Foglio6!B:B,0) -> 19 | I13: =SUM(_xlfn.XLOOKUP(A13,Foglio6!A:A,Foglio6!E:E,0),_xlfn.XLOOKUP(A13,Foglio6!A:A,Foglio6!F:F,0)) -> 0 | L13: 1 | P13: Alajbegovic
A14: Busio | B14: Venezia | C14: 24 | D14: C | E14: M/C | F14: 7 | H14: =_xlfn.XLOOKUP(A14,Foglio6!A:A,Foglio6!B:B,0) -> 19 | I14: =SUM(_xlfn.XLOOKUP(A14,Foglio6!A:A,Foglio6!E:E,0),_xlfn.XLOOKUP(A14,Foglio6!A:A,Foglio6!F:F,0)) -> 3 | L14: 1 | P14: Frattessi
A15: Pulisic | B15: Milan | C15: 28 | D15: C | E15: T/A | F15: 90 | G15: 0 | H15: =_xlfn.XLOOKUP(A15,Foglio6!A:A,Foglio6!B:B,0) -> 18 | I15: =SUM(_xlfn.XLOOKUP(A15,Foglio6!A:A,Foglio6!E:E,0),_xlfn.XLOOKUP(A15,Foglio6!A:A,Foglio6!F:F,0)) -> 4 | J15: 0 | K15: 0 | L15: 2 | P15: Ederson
A16: Zaccagni | B16: Lazio | C16: 31 | D16: C | E16: W/A | F16: 46 | H16: =_xlfn.XLOOKUP(A16,Foglio6!A:A,Foglio6!B:B,0) -> 18 | I16: =SUM(_xlfn.XLOOKUP(A16,Foglio6!A:A,Foglio6!E:E,0),_xlfn.XLOOKUP(A16,Foglio6!A:A,Foglio6!F:F,0)) -> 5 | L16: 1 | P16: Curtis Jones
A17: Atta | B17: Fiorentina | C17: 23 | D17: C | E17: C/T | F17: 44 | H17: =_xlfn.XLOOKUP(A17,Foglio6!A:A,Foglio6!B:B,0) -> 18 | I17: =SUM(_xlfn.XLOOKUP(A17,Foglio6!A:A,Foglio6!E:E,0),_xlfn.XLOOKUP(A17,Foglio6!A:A,Foglio6!F:F,0)) -> 1 | L17: 2 | P17: Saelemakers
A18: Vlasic | B18: Torino | C18: 29 | D18: C | E18: T | F18: 40 | H18: =_xlfn.XLOOKUP(A18,Foglio6!A:A,Foglio6!B:B,0) -> 18 | I18: =SUM(_xlfn.XLOOKUP(A18,Foglio6!A:A,Foglio6!E:E,0),_xlfn.XLOOKUP(A18,Foglio6!A:A,Foglio6!F:F,0)) -> 6 | L18: 1 | P18: Taylor K.
A19: Taylor K. | B19: Lazio | C19: 24 | D19: C | E19: C/T | F19: 32 | H19: =_xlfn.XLOOKUP(A19,Foglio6!A:A,Foglio6!B:B,0) -> 18 | I19: =SUM(_xlfn.XLOOKUP(A19,Foglio6!A:A,Foglio6!E:E,0),_xlfn.XLOOKUP(A19,Foglio6!A:A,Foglio6!F:F,0)) -> 2 | L19: 1 | P19: Moreira
A20: Ederson D.S. | B20: Atalanta | C20: 27 | D20: C | E20: M/C | F20: 23 | H20: =_xlfn.XLOOKUP(A20,Foglio6!A:A,Foglio6!B:B,0) -> 18 | I20: =SUM(_xlfn.XLOOKUP(A20,Foglio6!A:A,Foglio6!E:E,0),_xlfn.XLOOKUP(A20,Foglio6!A:A,Foglio6!F:F,0)) -> 0 | L20: 2 | P20: Politano
A21: Konè M. | B21: Roma | C21: 25 | D21: C | E21: M/C | F21: 21 | H21: =_xlfn.XLOOKUP(A21,Foglio6!A:A,Foglio6!B:B,0) -> 18 | I21: =SUM(_xlfn.XLOOKUP(A21,Foglio6!A:A,Foglio6!E:E,0),_xlfn.XLOOKUP(A21,Foglio6!A:A,Foglio6!F:F,0)) -> 0 | L21: 2
A22: Bernabè | B22: Parma | C22: 25 | D22: C | E22: C | F22: 18 | H22: =_xlfn.XLOOKUP(A22,Foglio6!A:A,Foglio6!B:B,0) -> 18 | I22: =SUM(_xlfn.XLOOKUP(A22,Foglio6!A:A,Foglio6!E:E,0),_xlfn.XLOOKUP(A22,Foglio6!A:A,Foglio6!F:F,0)) -> 3 | L22: 1
A23: Locatelli | B23: Juventus | C23: 28 | D23: C | E23: M/C | F23: 16 | H23: =_xlfn.XLOOKUP(A23,Foglio6!A:A,Foglio6!B:B,0) -> 18 | I23: =SUM(_xlfn.XLOOKUP(A23,Foglio6!A:A,Foglio6!E:E,0),_xlfn.XLOOKUP(A23,Foglio6!A:A,Foglio6!F:F,0)) -> 0 | L23: 1 | O23: 5 | S23: 1
A24: Cristante | B24: Roma | C24: 31 | D24: C | E24: M/C | F24: 15 | H24: =_xlfn.XLOOKUP(A24,Foglio6!A:A,Foglio6!B:B,0) -> 18 | I24: =SUM(_xlfn.XLOOKUP(A24,Foglio6!A:A,Foglio6!E:E,0),_xlfn.XLOOKUP(A24,Foglio6!A:A,Foglio6!F:F,0)) -> 0 | L24: 1
A25: Frendrup | B25: Genoa | C25: 25 | D25: C | E25: M/C | F25: 10 | H25: =_xlfn.XLOOKUP(A25,Foglio6!A:A,Foglio6!B:B,0) -> 18 | I25: =SUM(_xlfn.XLOOKUP(A25,Foglio6!A:A,Foglio6!E:E,0),_xlfn.XLOOKUP(A25,Foglio6!A:A,Foglio6!F:F,0)) -> 0 | L25: 2
A26: Karlstrom | B26: Udinese | C26: 31 | D26: C | E26: M/C | F26: 10 | H26: =_xlfn.XLOOKUP(A26,Foglio6!A:A,Foglio6!B:B,0) -> 18 | I26: =SUM(_xlfn.XLOOKUP(A26,Foglio6!A:A,Foglio6!E:E,0),_xlfn.XLOOKUP(A26,Foglio6!A:A,Foglio6!F:F,0)) -> 0 | L26: 1
A27: Pierotti | B27: Lecce | C27: 25 | D27: C | E27: W | F27: 10 | H27: =_xlfn.XLOOKUP(A27,Foglio6!A:A,Foglio6!B:B,0) -> 18 | I27: =SUM(_xlfn.XLOOKUP(A27,Foglio6!A:A,Foglio6!E:E,0),_xlfn.XLOOKUP(A27,Foglio6!A:A,Foglio6!F:F,0)) -> 3 | L27: 1
A28: Cacciamani | B28: Torino | C28: 19 | D28: C | E28: E/W | F28: 9 | H28: =_xlfn.XLOOKUP(A28,Foglio6!A:A,Foglio6!B:B,0) -> 18 | I28: =SUM(_xlfn.XLOOKUP(A28,Foglio6!A:A,Foglio6!E:E,0),_xlfn.XLOOKUP(A28,Foglio6!A:A,Foglio6!F:F,0)) -> 0 | L28: 1
A29: Keita M. | B29: Parma | C29: 24 | D29: C | E29: M/C | F29: 8 | H29: =_xlfn.XLOOKUP(A29,Foglio6!A:A,Foglio6!B:B,0) -> 18 | I29: =SUM(_xlfn.XLOOKUP(A29,Foglio6!A:A,Foglio6!E:E,0),_xlfn.XLOOKUP(A29,Foglio6!A:A,Foglio6!F:F,0)) -> 0 | L29: 1
A30: Matic | B30: Sassuolo | C30: 38 | D30: C | E30: M/C | F30: 8 | H30: =_xlfn.XLOOKUP(A30,Foglio6!A:A,Foglio6!B:B,0) -> 18 | I30: =SUM(_xlfn.XLOOKUP(A30,Foglio6!A:A,Foglio6!E:E,0),_xlfn.XLOOKUP(A30,Foglio6!A:A,Foglio6!F:F,0)) -> 0 | L30: 1
A31: Da Cunha | B31: Como | C31: 25 | D31: C | E31: C/T | F31: 45 | H31: =_xlfn.XLOOKUP(A31,Foglio6!A:A,Foglio6!B:B,0) -> 17 | I31: =SUM(_xlfn.XLOOKUP(A31,Foglio6!A:A,Foglio6!E:E,0),_xlfn.XLOOKUP(A31,Foglio6!A:A,Foglio6!F:F,0)) -> 4 | L31: 1
A32: McKennie | B32: Juventus | C32: 28 | D32: C | E32: C | F32: 34 | H32: =_xlfn.XLOOKUP(A32,Foglio6!A:A,Foglio6!B:B,0) -> 17 | I32: =SUM(_xlfn.XLOOKUP(A32,Foglio6!A:A,Foglio6!E:E,0),_xlfn.XLOOKUP(A32,Foglio6!A:A,Foglio6!F:F,0)) -> 0 | L32: 2
A33: Mastantuono | B33: Fiorentina | C33: 19 | D33: C | E33: W/T | F33: 29 | H33: =_xlfn.XLOOKUP(A33,Foglio6!A:A,Foglio6!B:B,0) -> 17 | I33: =SUM(_xlfn.XLOOKUP(A33,Foglio6!A:A,Foglio6!E:E,0),_xlfn.XLOOKUP(A33,Foglio6!A:A,Foglio6!F:F,0)) -> 2 | L33: 2
A34: Perrone | B34: Como | C34: 23 | D34: C | E34: M/C | F34: 19 | H34: =_xlfn.XLOOKUP(A34,Foglio6!A:A,Foglio6!B:B,0) -> 17 | I34: =SUM(_xlfn.XLOOKUP(A34,Foglio6!A:A,Foglio6!E:E,0),_xlfn.XLOOKUP(A34,Foglio6!A:A,Foglio6!F:F,0)) -> 0 | L34: 1 | O34: 1 | S34: 1
A35: Colpani | B35: Monza | C35: 27 | D35: C | E35: T | F35: 13 | H35: =_xlfn.XLOOKUP(A35,Foglio6!A:A,Foglio6!B:B,0) -> 17 | I35: =SUM(_xlfn.XLOOKUP(A35,Foglio6!A:A,Foglio6!E:E,0),_xlfn.XLOOKUP(A35,Foglio6!A:A,Foglio6!F:F,0)) -> 2 | L35: 1
A36: Fazzini | B36: Cagliari | C36: 23 | D36: C | E36: C/T | F36: 10 | H36: =_xlfn.XLOOKUP(A36,Foglio6!A:A,Foglio6!B:B,0) -> 17 | I36: =SUM(_xlfn.XLOOKUP(A36,Foglio6!A:A,Foglio6!E:E,0),_xlfn.XLOOKUP(A36,Foglio6!A:A,Foglio6!F:F,0)) -> 3 | L36: 1
A37: Akinsanmiro | B37: Monza | C37: 22 | D37: C | E37: C | F37: 8 | G37: 0 | H37: =_xlfn.XLOOKUP(A37,Foglio6!A:A,Foglio6!B:B,0) -> 17 | I37: =SUM(_xlfn.XLOOKUP(A37,Foglio6!A:A,Foglio6!E:E,0),_xlfn.XLOOKUP(A37,Foglio6!A:A,Foglio6!F:F,0)) -> 0 | L37: 1
A38: Rovella | B38: Lazio | C38: 25 | D38: C | E38: M/C | F38: 8 | H38: =_xlfn.XLOOKUP(A38,Foglio6!A:A,Foglio6!B:B,0) -> 17 | I38: =SUM(_xlfn.XLOOKUP(A38,Foglio6!A:A,Foglio6!E:E,0),_xlfn.XLOOKUP(A38,Foglio6!A:A,Foglio6!F:F,0)) -> 3 | L38: 1
A39: Adopo | B39: Cagliari | C39: 26 | D39: C | E39: M/C | F39: 7 | G39: 0 | H39: =_xlfn.XLOOKUP(A39,Foglio6!A:A,Foglio6!B:B,0) -> 17 | I39: =SUM(_xlfn.XLOOKUP(A39,Foglio6!A:A,Foglio6!E:E,0),_xlfn.XLOOKUP(A39,Foglio6!A:A,Foglio6!F:F,0)) -> 0 | J39: 0 | K39: 0
A40: Winks | B40: Cagliari | C40: 30 | D40: C | E40: M/C | F40: 7 | H40: =_xlfn.XLOOKUP(A40,Foglio6!A:A,Foglio6!B:B,0) -> 17 | I40: =SUM(_xlfn.XLOOKUP(A40,Foglio6!A:A,Foglio6!E:E,0),_xlfn.XLOOKUP(A40,Foglio6!A:A,Foglio6!F:F,0)) -> 1
...

Sheet att
A1: Adams A. | B1: Venezia | C1: 26 | D1: A | E1: Pc | F1: 26 | G1: 0 | H1: =_xlfn.XLOOKUP(A1,Foglio6!A:A,Foglio6!B:B,0) -> 19 | K1: lautaro | M1: dybala
A2: Adams C. | B2: Torino | C2: 30 | D2: A | E2: A | F2: 16 | G2: 0 | H2: =_xlfn.XLOOKUP(A2,Foglio6!A:A,Foglio6!B:B,0) -> 2 | K2: malen | M2: scamacca
A3: Davis K. | B3: Udinese | C3: 28 | D3: A | E3: Pc | F3: 61 | G3: 0 | H3: =_xlfn.XLOOKUP(A3,Foglio6!A:A,Foglio6!B:B,0) -> 19 | K3: hojlund | M3: davis
A4: Simeone | B4: Torino | C4: 31 | D4: A | E4: Pc | F4: 41 | H4: =_xlfn.XLOOKUP(A4,Foglio6!A:A,Foglio6!B:B,0) -> 19 | K4: kolo muani | M4: leao
A5: Martinez L. | B5: Inter | C5: 29 | D5: A | E5: Pc | F5: 185 | G5: 0 | H5: =_xlfn.XLOOKUP(A5,Foglio6!A:A,Foglio6!B:B,0) -> 18 | K5: douvikas | M5: de ketelaere
A6: Malen | B6: Roma | C6: 27 | D6: A | E6: Pc | F6: 183 | G6: 0 | H6: =_xlfn.XLOOKUP(A6,Foglio6!A:A,Foglio6!B:B,0) -> 18 | K6: thuram
A7: Hojlund | B7: Napoli | C7: 23 | D7: A | E7: Pc | F7: 136 | G7: 0 | H7: =_xlfn.XLOOKUP(A7,Foglio6!A:A,Foglio6!B:B,0) -> 18 | K7: kean
A8: Ramos G. | B8: Milan | C8: 25 | D8: A | E8: Pc | F8: 116 | G8: 0 | H8: =_xlfn.XLOOKUP(A8,Foglio6!A:A,Foglio6!B:B,0) -> 18 | K8: g.ramos
A9: Kolo Muani | B9: Juventus | C9: 28 | D9: A | E9: Pc | F9: 113 | G9: 0 | H9: =_xlfn.XLOOKUP(A9,Foglio6!A:A,Foglio6!B:B,0) -> 18 | K9: yildiz
A10: Douvikas | B10: Como | C10: 27 | D10: A | E10: Pc | F10: 79 | G10: 0 | H10: =_xlfn.XLOOKUP(A10,Foglio6!A:A,Foglio6!B:B,0) -> 18 | K10: simeone
A11: Berardi | B11: Sassuolo | C11: 32 | D11: A | E11: A | F11: 58 | G11: 0 | H11: =_xlfn.XLOOKUP(A11,Foglio6!A:A,Foglio6!B:B,0) -> 18
A12: Laurientè | B12: Sassuolo | C12: 28 | D12: A | E12: A | F12: 44 | G12: 0 | H12: =_xlfn.XLOOKUP(A12,Foglio6!A:A,Foglio6!B:B,0) -> 18
A13: Colombo | B13: Genoa | C13: 24 | D13: A | E13: Pc | F13: 32 | H13: =_xlfn.XLOOKUP(A13,Foglio6!A:A,Foglio6!B:B,0) -> 18
A14: Raimondo | B14: Frosinone | C14: 22 | D14: A | E14: Pc | F14: 12 | H14: =_xlfn.XLOOKUP(A14,Foglio6!A:A,Foglio6!B:B,0) -> 18
A15: Maldini | B15: Cagliari | C15: 25 | D15: A | E15: T/A | F15: 11 | H15: =_xlfn.XLOOKUP(A15,Foglio6!A:A,Foglio6!B:B,0) -> 18
A16: Thuram | B16: Inter | C16: 29 | D16: A | E16: Pc | F16: 140 | G16: 0 | H16: =_xlfn.XLOOKUP(A16,Foglio6!A:A,Foglio6!B:B,0) -> 17
A17: Yildiz | B17: Juventus | C17: 21 | D17: A | E17: A | F17: 96 | G17: 0 | H17: =_xlfn.XLOOKUP(A17,Foglio6!A:A,Foglio6!B:B,0) -> 17
A18: De Ketelaere | B18: Atalanta | C18: 25 | D18: A | E18: A | F18: 53 | G18: 0 | H18: =_xlfn.XLOOKUP(A18,Foglio6!A:A,Foglio6!B:B,0) -> 17
A19: Santos A. | B19: Napoli | C19: 24 | D19: A | E19: W/A | F19: 29 | H19: =_xlfn.XLOOKUP(A19,Foglio6!A:A,Foglio6!B:B,0) -> 17
A20: Tourè E. | B20: Parma | C20: 25 | D20: A | E20: Pc | F20: 22 | H20: =_xlfn.XLOOKUP(A20,Foglio6!A:A,Foglio6!B:B,0) -> 17
A21: Cutrone | B21: Monza | C21: 28 | D21: A | E21: Pc | F21: 17 | H21: =_xlfn.XLOOKUP(A21,Foglio6!A:A,Foglio6!B:B,0) -> 17
A22: Kean | B22: Fiorentina | C22: 26 | D22: A | E22: Pc | F22: 100 | G22: 0 | H22: =_xlfn.XLOOKUP(A22,Foglio6!A:A,Foglio6!B:B,0) -> 16
A23: Dybala | B23: Roma | C23: 33 | D23: A | E23: A | F23: 34 | H23: =_xlfn.XLOOKUP(A23,Foglio6!A:A,Foglio6!B:B,0) -> 16
A24: Yeboah J. | B24: Venezia | C24: 26 | D24: A | E24: A | F24: 14 | H24: =_xlfn.XLOOKUP(A24,Foglio6!A:A,Foglio6!B:B,0) -> 16
A25: Vitinha O. | B25: Genoa | C25: 26 | D25: A | E25: A | F25: 10 | H25: =_xlfn.XLOOKUP(A25,Foglio6!A:A,Foglio6!B:B,0) -> 16
A26: N'Dri | B26: Lecce | C26: 26 | D26: A | E26: W/A | F26: 5 | H26: =_xlfn.XLOOKUP(A26,Foglio6!A:A,Foglio6!B:B,0) -> 16
A27: Raspadori | B27: Atalanta | C27: 26 | D27: A | E27: A | F27: 31 | H27: =_xlfn.XLOOKUP(A27,Foglio6!A:A,Foglio6!B:B,0) -> 15
A28: Diao | B28: Como | C28: 21 | D28: A | E28: W/A | F28: 25 | H28: =_xlfn.XLOOKUP(A28,Foglio6!A:A,Foglio6!B:B,0) -> 15
A29: Geubbels | B29: Lecce | C29: 25 | D29: A | E29: Pc | F29: 13 | H29: =_xlfn.XLOOKUP(A29,Foglio6!A:A,Foglio6!B:B,0) -> 15
A30: Scamacca | B30: Atalanta | C30: 27 | D30: A | E30: Pc | F30: 66 | G30: 0 | H30: =_xlfn.XLOOKUP(A30,Foglio6!A:A,Foglio6!B:B,0) -> 14.5
A31: Leao | B31: Milan | C31: 27 | D31: A | E31: A | F31: 60 | G31: 0 | H31: =_xlfn.XLOOKUP(A31,Foglio6!A:A,Foglio6!B:B,0) -> 14
A32: Dovbyk | B32: Bologna | C32: 29 | D32: A | E32: Pc | F32: 37 | H32: =_xlfn.XLOOKUP(A32,Foglio6!A:A,Foglio6!B:B,0) -> 13.5
A33: Mota | B33: Monza | C33: 28 | D33: A | E33: A | F33: 9 | H33: =_xlfn.XLOOKUP(A33,Foglio6!A:A,Foglio6!B:B,0) -> 13.5
A34: Pinamonti | B34: Sassuolo | C34: 27 | D34: A | E34: Pc | F34: 28 | H34: =_xlfn.XLOOKUP(A34,Foglio6!A:A,Foglio6!B:B,0) -> 13
A35: Romero D. | B35: Parma | C35: 23 | D35: A | E35: Pc | F35: 19 | H35: =_xlfn.XLOOKUP(A35,Foglio6!A:A,Foglio6!B:B,0) -> 13
A36: Ghedjemis | B36: Frosinone | C36: 24 | D36: A | E36: W/A | F36: 15 | H36: =_xlfn.XLOOKUP(A36,Foglio6!A:A,Foglio6!B:B,0) -> 13
A37: Kvernadze | B37: Frosinone | C37: 23 | D37: A | E37: W/A | F37: 8 | H37: =_xlfn.XLOOKUP(A37,Foglio6!A:A,Foglio6!B:B,0) -> 12
A38: Frigan | B38: Parma | C38: 23 | D38: A | E38: A | F38: 7 | H38: =_xlfn.XLOOKUP(A38,Foglio6!A:A,Foglio6!B:B,0) -> 12
A39: Kevin Carlos | B39: Cagliari | C39: 25 | D39: A | E39: Pc | F39: 24 | H39: =_xlfn.XLOOKUP(A39,Foglio6!A:A,Foglio6!B:B,0) -> 11
A40: Dia | B40: Lazio | C40: 30 | D40: A | E40: A | F40: 16 | H40: =_xlfn.XLOOKUP(A40,Foglio6!A:A,Foglio6!B:B,0) -> 8
...

Sheet low cost
A3: Akinsanmiro | B3: Monza | C3: 22 | D3: C | E3: C | F3: 8
A4: Cacciamani | B4: Torino | C4: 19 | D4: C | E4: E/W | F4: 9
A5: Calò | B5: Frosinone | C5: 29 | D5: C | E5: M/C | F5: 13
A6: Monterisi
A7: Marusic
A8: Kamara
A9: Obert
A10: GALLO
A11: Mitaj
A12: Idzes
A13: Coco
A14: Mkhitaryan
A15: Piotrowski
A16: Zalewski
A17: Perez K.
... A29: Adams c.

Sheet 60 att titolari
A1: Adams A. | B1: Venezia | C1: 26 | D1: A | E1: Pc | F1: 26 | G1: 19 | L1: 1 credito
A2: Davis K. | B2: Udinese | C2: 28 | D2: A | E2: Pc | F2: 61 | G2: 19 | L2: Adams A. | M2: Venezia | N2: 26 | O2: A | P2: Pc | Q2: 26 | R2: 19 | S2: 1
A3: Simeone | B3: Torino | C3: 31 | D3: A | E3: Pc | F3: 41 | G3: 19 | L3: Yeboah J. | M3: Venezia | N3: 26 | O3: A | P3: A | Q3: 14 | R3: 16 | S3: 1
A4: Martinez L. | B4: Inter | C4: 29 | D4: A | E4: Pc | F4: 185 | G4: 18 | L4: Vitinha O. | M4: Genoa | N4: 26 | O4: A | P4: A | Q4: 10 | R4: 16 | S4: 1
A5: Malen | B5: Roma | C5: 27 | D5: A | E5: Pc | F5: 183 | G5: 18 | L5: N'Dri | M5: Lecce | N5: 26 | O5: A | P5: W/A | Q5: 5 | R5: 16 | S5: 1
A6: Hojlund | B6: Napoli | C6: 23 | D6: A | E6: Pc | F6: 136 | G6: 18 | L6: Elphege | M6: Parma | N6: 25 | O6: A | P6: Pc | Q6: 6 | R6: 8 | S6: 1
A7: Ramos G. | B7: Milan | C7: 25 | D7: A | E7: Pc | F7: 116 | G7: 18 | L7: Bowie | M7: Sassuolo | N7: 24 | O7: A | P7: Pc | Q7: 20 | R7: 7
A8: Kolo Muani | B8: Juventus | C8: 28 | D8: A | E8: Pc | F8: 113 | G8: 18 | L8: Borrelli | M8: Cagliari | N8: 26 | O8: A | P8: Pc | Q8: 5 | R8: 5
A9: Douvikas | B9: Como | C9: 27 | D9: A | E9: Pc | F9: 79 | G9: 18 | L9: Esposito F.P. | M9: Inter | N9: 21 | O9: A | P9: Pc | Q9: 47 | R9: 2
A10: Berardi | B10: Sassuolo | C10: 32 | D10: A | E10: A | F10: 58 | G10: 18 | L10: Pellegrino M. | M10: Fiorentina | N10: 25 | O10: A | P10: Pc | Q10: 30 | R10: 2
A11: Laurientè | B11: Sassuolo | C11: 28 | D11: A | E11: A | F11: 44 | G11: 18 | L11: Adams C. | M11: Torino | N11: 30 | O11: A | P11: A | Q11: 16 | R11: 2
A12: Colombo | B12: Genoa | C12: 24 | D12: A | E12: Pc | F12: 32 | G12: 18 | L12: Mendy P. | M12: Cagliari | N12: 19 | O12: A | P12: Pc | Q12: 5 | R12: 5
A13: Raimondo | B13: Frosinone | C13: 22 | D13: A | E13: Pc | F13: 12 | G13: 18 | L13: Noslin | M13: Lazio | N13: 27 | O13: A | P13: A | Q13: 9 | R13: 4
A14: Maldini | B14: Cagliari | C14: 25 | D14: A | E14: T/A | F14: 11 | G14: 18
A15: Thuram | B15: Inter | C15: 29 | D15: A | E15: Pc | F15: 140 | G15: 17
A16: Yildiz | B16: Juventus | C16: 21 | D16: A | E16: A | F16: 96 | G16: 17
A17: De Ketelaere | B17: Atalanta | C17: 25 | D17: A | E17: A | F17: 53 | G17: 17
A18: Santos A. | B18: Napoli | C18: 24 | D18: A | E18: W/A | F18: 29 | G18: 17
A19: Tourè E. | B19: Parma | C19: 25 | D19: A | E19: Pc | F19: 22 | G19: 17
A20: Cutrone | B20: Monza | C20: 28 | D20: A | E20: Pc | F20: 17 | G20: 17
A21: Kean | B21: Fiorentina | C21: 26 | D21: A | E21: Pc | F21: 100 | G21: 16
A22: Dybala | B22: Roma | C22: 33 | D22: A | E22: A | F22: 34 | G22: 16
A23: Yeboah J. | B23: Venezia | C23: 26 | D23: A | E23: A | F23: 14 | G23: 16
A24: Vitinha O. | B24: Genoa | C24: 26 | D24: A | E24: A | F24: 10 | G24: 16
A25: N'Dri | B25: Lecce | C25: 26 | D25: A | E25: W/A | F25: 5 | G25: 16
... A60: David | B60: Juventus | C60: 26 | D60: A | E60: Pc | F60: 20 | G60: 0

Sheet 80 difensori titolari
A1: Dimarco | B1: Inter | C1: 29 | D1: D | E1: E/W | F1: 133 | G1: 19 | H1: 2
A2: Tiago Gabriel | B2: Lecce | C2: 22 | D2: D | E2: Dc | F2: 9 | G2: 19 | H2: 0
A3: Molina N. | B3: Roma | C3: 28 | D3: D | E3: E | F3: 44 | G3: 18 | H3: 0
A4: Wesley | B4: Roma | C4: 23 | D4: D | E4: E | F4: 42 | G4: 18 | H4: 0
A5: Akanji | B5: Inter | C5: 31 | D5: D | E5: Dc | F5: 28 | G5: 18 | H5: 0
A6: Mancini | B6: Roma | C6: 30 | D6: D | E6: Dc | F6: 25 | G6: 18 | H6: 0
A7: Bastoni | B7: Inter | C7: 27 | D7: D | E7: Dc | F7: 22 | G7: 18 | H7: 0
A8: Bremer | B8: Juventus | C8: 29 | D8: D | E8: Dc | F8: 25 | G8: 18 | H8: 0
A9: Pavlovic | B9: Milan | C9: 25 | D9: D | E9: Dc | F9: 24 | G9: 18 | H9: 0
A10: Rrahmani | B10: Napoli | C10: 32 | D10: D | E10: Dc | F10: 24 | G10: 18 | H10: 0
A11: Solet | B11: Udinese | C11: 26 | D11: D | E11: Dc | F11: 23 | G11: 18 | H11: 2
A12: N'Dicka | B12: Roma | C12: 27 | D12: D | E12: Dc | F12: 22 | G12: 18 | H12: 0
... A80: Kouadio | B80: Monza | C80: 20 | D80: D | E80: Dd/Dc | F80: 5 | G80: 11 | H80: 0

Sheet 80 cc titolari
A1: Paz N. | B1: Como | C1: 22 | D1: C | E1: T/A | F1: 125 | G1: 19
A2: McTominay | B2: Napoli | C2: 30 | D2: C | E2: C/T | F2: 120 | G2: 19
A3: Calhanoglu | B3: Inter | C3: 32 | D3: C | E3: M/C | F3: 115 | G3: 19
A4: Orsolini | B4: Bologna | C4: 29 | D4: C | E4: W/A | F4: 100 | G4: 19
A5: Rabiot | B5: Milan | C5: 31 | D5: C | E5: C/T | F5: 64 | G5: 19
A6: Zaniolo | B6: Udinese | C6: 27 | D6: C | E6: T/A | F6: 50 | G6: 19
A7: Barella | B7: Inter | C7: 29 | D7: C | E7: C | F7: 40 | G7: 19
A8: Modric | B8: Milan | C8: 41 | D8: C | E8: M/C | F8: 25 | G8: 19
A9: Ekkelenkamp | B9: Udinese | C9: 26 | D9: C | E9: C/T | F9: 21 | G9: 19
A10: Basic | B10: Venezia | C10: 30 | D10: C | E10: M/C | F10: 10 | G10: 19
A11: Lobotka | B11: Napoli | C11: 32 | D11: C | E11: M/C | F11: 10 | G11: 19
A12: Busio | B12: Venezia | C12: 24 | D12: C | E12: M/C | F12: 7 | G12: 19
... A80: Berisha M. | B80: Lecce | C80: 23 | D80: C | E80: C/T | F80: 8 | G80: 8
